Process A [NEW] (arrival time 9 ms) 16 CPU bursts
Process B [NEW] (arrival time 18 ms) 21 CPU bursts
Process C [NEW] (arrival time 84 ms) 82 CPU bursts
Process D [NEW] (arrival time 86 ms) 36 CPU bursts
Process E [NEW] (arrival time 2 ms) 26 CPU bursts
Process F [NEW] (arrival time 25 ms) 39 CPU bursts
Process G [NEW] (arrival time 13 ms) 76 CPU bursts
Process H [NEW] (arrival time 46 ms) 82 CPU bursts
Process I [NEW] (arrival time 64 ms) 63 CPU bursts
Process J [NEW] (arrival time 31 ms) 21 CPU bursts
Process K [NEW] (arrival time 56 ms) 1 CPU burst
Process L [NEW] (arrival time 12 ms) 3 CPU bursts
time 0ms: Simulator started for SJF [Q <empty>]
time 2ms: Process E (tau 100ms) arrived; added to ready queue [Q E]
time 4ms: Process E started using the CPU for 11ms burst [Q <empty>]
time 9ms: Process A (tau 100ms) arrived; added to ready queue [Q A]
time 12ms: Process L (tau 100ms) arrived; added to ready queue [Q A L]
time 13ms: Process G (tau 100ms) arrived; added to ready queue [Q A G L]
time 15ms: Process E completed a CPU burst; 25 bursts to go [Q A G L]
time 15ms: Recalculated tau = 56ms for process E [Q A G L]
time 15ms: Process E switching out of CPU; will block on I/O until time 34ms [Q A G L]
time 18ms: Process B (tau 100ms) arrived; added to ready queue [Q B G L]
time 19ms: Process A started using the CPU for 56ms burst [Q B G L]
time 25ms: Process F (tau 100ms) arrived; added to ready queue [Q B F G L]
time 31ms: Process J (tau 100ms) arrived; added to ready queue [Q B F G J L]
time 34ms: Process E (tau 56ms) completed I/O; added to ready queue [Q E B F G J L]
time 46ms: Process H (tau 100ms) arrived; added to ready queue [Q E B F G H J L]
time 56ms: Process K (tau 100ms) arrived; added to ready queue [Q E B F G H J K L]
time 64ms: Process I (tau 100ms) arrived; added to ready queue [Q E B F G H I J K L]
time 75ms: Process A completed a CPU burst; 15 bursts to go [Q E B F G H I J K L]
time 75ms: Recalculated tau = 78ms for process A [Q E B F G H I J K L]
time 75ms: Process A switching out of CPU; will block on I/O until time 100ms [Q E B F G H I J K L]
time 79ms: Process E started using the CPU for 65ms burst [Q B F G H I J K L]
time 84ms: Process C (tau 100ms) arrived; added to ready queue [Q B C F G H I J K L]
time 86ms: Process D (tau 100ms) arrived; added to ready queue [Q B C D F G H I J K L]
time 100ms: Process A (tau 78ms) completed I/O; added to ready queue [Q A B C D F G H I J K L]
time 144ms: Process E completed a CPU burst; 24 bursts to go [Q A B C D F G H I J K L]
time 144ms: Recalculated tau = 61ms for process E [Q A B C D F G H I J K L]
time 144ms: Process E switching out of CPU; will block on I/O until time 201ms [Q A B C D F G H I J K L]
time 148ms: Process A started using the CPU for 60ms burst [Q B C D F G H I J K L]
time 201ms: Process E (tau 61ms) completed I/O; added to ready queue [Q E B C D F G H I J K L]
time 208ms: Process A completed a CPU burst; 14 bursts to go [Q E B C D F G H I J K L]
time 208ms: Recalculated tau = 69ms for process A [Q E B C D F G H I J K L]
time 208ms: Process A switching out of CPU; will block on I/O until time 363ms [Q E B C D F G H I J K L]
time 212ms: Process E started using the CPU for 52ms burst [Q B C D F G H I J K L]
time 264ms: Process E completed a CPU burst; 23 bursts to go [Q B C D F G H I J K L]
time 264ms: Recalculated tau = 57ms for process E [Q B C D F G H I J K L]
time 264ms: Process E switching out of CPU; will block on I/O until time 362ms [Q B C D F G H I J K L]
time 268ms: Process B started using the CPU for 106ms burst [Q C D F G H I J K L]
time 362ms: Process E (tau 57ms) completed I/O; added to ready queue [Q E C D F G H I J K L]
time 363ms: Process A (tau 69ms) completed I/O; added to ready queue [Q E A C D F G H I J K L]
time 374ms: Process B completed a CPU burst; 20 bursts to go [Q E A C D F G H I J K L]
time 374ms: Recalculated tau = 103ms for process B [Q E A C D F G H I J K L]
time 374ms: Process B switching out of CPU; will block on I/O until time 532ms [Q E A C D F G H I J K L]
time 378ms: Process E started using the CPU for 199ms burst [Q A C D F G H I J K L]
time 532ms: Process B (tau 103ms) completed I/O; added to ready queue [Q A C D F G H I J K L B]
time 577ms: Process E completed a CPU burst; 22 bursts to go [Q A C D F G H I J K L B]
time 577ms: Recalculated tau = 128ms for process E [Q A C D F G H I J K L B]
time 577ms: Process E switching out of CPU; will block on I/O until time 589ms [Q A C D F G H I J K L B]
time 581ms: Process A started using the CPU for 39ms burst [Q C D F G H I J K L B]
time 589ms: Process E (tau 128ms) completed I/O; added to ready queue [Q C D F G H I J K L B E]
time 620ms: Process A completed a CPU burst; 13 bursts to go [Q C D F G H I J K L B E]
time 620ms: Recalculated tau = 54ms for process A [Q C D F G H I J K L B E]
time 620ms: Process A switching out of CPU; will block on I/O until time 672ms [Q C D F G H I J K L B E]
time 624ms: Process C started using the CPU for 79ms burst [Q D F G H I J K L B E]
time 672ms: Process A (tau 54ms) completed I/O; added to ready queue [Q A D F G H I J K L B E]
time 703ms: Process C completed a CPU burst; 81 bursts to go [Q A D F G H I J K L B E]
time 703ms: Recalculated tau = 90ms for process C [Q A D F G H I J K L B E]
time 703ms: Process C switching out of CPU; will block on I/O until time 862ms [Q A D F G H I J K L B E]
time 707ms: Process A started using the CPU for 47ms burst [Q D F G H I J K L B E]
time 754ms: Process A completed a CPU burst; 12 bursts to go [Q D F G H I J K L B E]
time 754ms: Recalculated tau = 51ms for process A [Q D F G H I J K L B E]
time 754ms: Process A switching out of CPU; will block on I/O until time 758ms [Q D F G H I J K L B E]
time 758ms: Process D started using the CPU for 22ms burst [Q F G H I J K L B E]
time 758ms: Process A (tau 51ms) completed I/O; added to ready queue [Q A F G H I J K L B E]
time 780ms: Process D completed a CPU burst; 35 bursts to go [Q A F G H I J K L B E]
time 780ms: Recalculated tau = 61ms for process D [Q A F G H I J K L B E]
time 780ms: Process D switching out of CPU; will block on I/O until time 797ms [Q A F G H I J K L B E]
time 784ms: Process A started using the CPU for 137ms burst [Q F G H I J K L B E]
time 797ms: Process D (tau 61ms) completed I/O; added to ready queue [Q D F G H I J K L B E]
time 862ms: Process C (tau 90ms) completed I/O; added to ready queue [Q D C F G H I J K L B E]
time 921ms: Process A completed a CPU burst; 11 bursts to go [Q D C F G H I J K L B E]
time 921ms: Recalculated tau = 94ms for process A [Q D C F G H I J K L B E]
time 921ms: Process A switching out of CPU; will block on I/O until time 947ms [Q D C F G H I J K L B E]
time 925ms: Process D started using the CPU for 52ms burst [Q C F G H I J K L B E]
time 947ms: Process A (tau 94ms) completed I/O; added to ready queue [Q C A F G H I J K L B E]
time 977ms: Process D completed a CPU burst; 34 bursts to go [Q C A F G H I J K L B E]
time 977ms: Recalculated tau = 57ms for process D [Q C A F G H I J K L B E]
time 977ms: Process D switching out of CPU; will block on I/O until time 988ms [Q C A F G H I J K L B E]
time 981ms: Process C started using the CPU for 148ms burst [Q A F G H I J K L B E]
time 988ms: Process D (tau 57ms) completed I/O; added to ready queue [Q D A F G H I J K L B E]
time 1129ms: Process C completed a CPU burst; 80 bursts to go [Q D A F G H I J K L B E]
time 1129ms: Recalculated tau = 119ms for process C [Q D A F G H I J K L B E]
time 1129ms: Process C switching out of CPU; will block on I/O until time 1133ms [Q D A F G H I J K L B E]
time 1133ms: Process D started using the CPU for 90ms burst [Q A F G H I J K L B E]
time 1133ms: Process C (tau 119ms) completed I/O; added to ready queue [Q A F G H I J K L B C E]
time 1223ms: Process D completed a CPU burst; 33 bursts to go [Q A F G H I J K L B C E]
time 1223ms: Recalculated tau = 74ms for process D [Q A F G H I J K L B C E]
time 1223ms: Process D switching out of CPU; will block on I/O until time 1229ms [Q A F G H I J K L B C E]
time 1227ms: Process A started using the CPU for 64ms burst [Q F G H I J K L B C E]
time 1229ms: Process D (tau 74ms) completed I/O; added to ready queue [Q D F G H I J K L B C E]
time 1291ms: Process A completed a CPU burst; 10 bursts to go [Q D F G H I J K L B C E]
time 1291ms: Recalculated tau = 79ms for process A [Q D F G H I J K L B C E]
time 1291ms: Process A switching out of CPU; will block on I/O until time 1308ms [Q D F G H I J K L B C E]
time 1295ms: Process D started using the CPU for 55ms burst [Q F G H I J K L B C E]
time 1308ms: Process A (tau 79ms) completed I/O; added to ready queue [Q A F G H I J K L B C E]
time 1350ms: Process D completed a CPU burst; 32 bursts to go [Q A F G H I J K L B C E]
time 1350ms: Recalculated tau = 65ms for process D [Q A F G H I J K L B C E]
time 1350ms: Process D switching out of CPU; will block on I/O until time 1382ms [Q A F G H I J K L B C E]
time 1354ms: Process A started using the CPU for 68ms burst [Q F G H I J K L B C E]
time 1382ms: Process D (tau 65ms) completed I/O; added to ready queue [Q D F G H I J K L B C E]
time 1422ms: Process A completed a CPU burst; 9 bursts to go [Q D F G H I J K L B C E]
time 1422ms: Recalculated tau = 74ms for process A [Q D F G H I J K L B C E]
time 1422ms: Process A switching out of CPU; will block on I/O until time 1488ms [Q D F G H I J K L B C E]
time 1426ms: Process D started using the CPU for 46ms burst [Q F G H I J K L B C E]
time 1472ms: Process D completed a CPU burst; 31 bursts to go [Q F G H I J K L B C E]
time 1472ms: Recalculated tau = 56ms for process D [Q F G H I J K L B C E]
time 1472ms: Process D switching out of CPU; will block on I/O until time 1657ms [Q F G H I J K L B C E]
time 1476ms: Process F started using the CPU for 24ms burst [Q G H I J K L B C E]
time 1488ms: Process A (tau 74ms) completed I/O; added to ready queue [Q A G H I J K L B C E]
time 1500ms: Process F completed a CPU burst; 38 bursts to go [Q A G H I J K L B C E]
time 1500ms: Recalculated tau = 62ms for process F [Q A G H I J K L B C E]
time 1500ms: Process F switching out of CPU; will block on I/O until time 1568ms [Q A G H I J K L B C E]
time 1504ms: Process A started using the CPU for 113ms burst [Q G H I J K L B C E]
time 1568ms: Process F (tau 62ms) completed I/O; added to ready queue [Q F G H I J K L B C E]
time 1617ms: Process A completed a CPU burst; 8 bursts to go [Q F G H I J K L B C E]
time 1617ms: Recalculated tau = 94ms for process A [Q F G H I J K L B C E]
time 1617ms: Process A switching out of CPU; will block on I/O until time 1635ms [Q F G H I J K L B C E]
time 1621ms: Process F started using the CPU for 15ms burst [Q G H I J K L B C E]
time 1635ms: Process A (tau 94ms) completed I/O; added to ready queue [Q A G H I J K L B C E]
time 1636ms: Process F completed a CPU burst; 37 bursts to go [Q A G H I J K L B C E]
time 1636ms: Recalculated tau = 39ms for process F [Q A G H I J K L B C E]
time 1636ms: Process F switching out of CPU; will block on I/O until time 1718ms [Q A G H I J K L B C E]
time 1640ms: Process A started using the CPU for 11ms burst [Q G H I J K L B C E]
time 1651ms: Process A completed a CPU burst; 7 bursts to go [Q G H I J K L B C E]
time 1651ms: Recalculated tau = 53ms for process A [Q G H I J K L B C E]
time 1651ms: Process A switching out of CPU; will block on I/O until time 1815ms [Q G H I J K L B C E]
time 1655ms: Process G started using the CPU for 76ms burst [Q H I J K L B C E]
time 1657ms: Process D (tau 56ms) completed I/O; added to ready queue [Q D H I J K L B C E]
time 1718ms: Process F (tau 39ms) completed I/O; added to ready queue [Q F D H I J K L B C E]
time 1731ms: Process G completed a CPU burst; 75 bursts to go [Q F D H I J K L B C E]
time 1731ms: Recalculated tau = 88ms for process G [Q F D H I J K L B C E]
time 1731ms: Process G switching out of CPU; will block on I/O until time 1876ms [Q F D H I J K L B C E]
time 1735ms: Process F started using the CPU for 1ms burst [Q D H I J K L B C E]
time 1736ms: Process F completed a CPU burst; 36 bursts to go [Q D H I J K L B C E]
time 1736ms: Recalculated tau = 20ms for process F [Q D H I J K L B C E]
time 1736ms: Process F switching out of CPU; will block on I/O until time 1794ms [Q D H I J K L B C E]
time 1740ms: Process D started using the CPU for 41ms burst [Q H I J K L B C E]
time 1781ms: Process D completed a CPU burst; 30 bursts to go [Q H I J K L B C E]
time 1781ms: Recalculated tau = 49ms for process D [Q H I J K L B C E]
time 1781ms: Process D switching out of CPU; will block on I/O until time 1804ms [Q H I J K L B C E]
time 1785ms: Process H started using the CPU for 9ms burst [Q I J K L B C E]
time 1794ms: Process H completed a CPU burst; 81 bursts to go [Q I J K L B C E]
time 1794ms: Recalculated tau = 55ms for process H [Q I J K L B C E]
time 1794ms: Process H switching out of CPU; will block on I/O until time 1975ms [Q I J K L B C E]
time 1794ms: Process F (tau 20ms) completed I/O; added to ready queue [Q F I J K L B C E]
time 1798ms: Process F started using the CPU for 25ms burst [Q I J K L B C E]
time 1804ms: Process D (tau 49ms) completed I/O; added to ready queue [Q D I J K L B C E]
time 1815ms: Process A (tau 53ms) completed I/O; added to ready queue [Q D A I J K L B C E]
time 1823ms: Process F completed a CPU burst; 35 bursts to go [Q D A I J K L B C E]
time 1823ms: Recalculated tau = 23ms for process F [Q D A I J K L B C E]
time 1823ms: Process F switching out of CPU; will block on I/O until time 1828ms [Q D A I J K L B C E]
time 1827ms: Process D started using the CPU for 117ms burst [Q A I J K L B C E]
time 1828ms: Process F (tau 23ms) completed I/O; added to ready queue [Q F A I J K L B C E]
time 1876ms: Process G (tau 88ms) completed I/O; added to ready queue [Q F A G I J K L B C E]
time 1944ms: Process D completed a CPU burst; 29 bursts to go [Q F A G I J K L B C E]
time 1944ms: Recalculated tau = 83ms for process D [Q F A G I J K L B C E]
time 1944ms: Process D switching out of CPU; will block on I/O until time 2047ms [Q F A G I J K L B C E]
time 1948ms: Process F started using the CPU for 47ms burst [Q A G I J K L B C E]
time 1975ms: Process H (tau 55ms) completed I/O; added to ready queue [Q A H G I J K L B C E]
time 1995ms: Process F completed a CPU burst; 34 bursts to go [Q A H G I J K L B C E]
time 1995ms: Recalculated tau = 35ms for process F [Q A H G I J K L B C E]
time 1995ms: Process F switching out of CPU; will block on I/O until time 2186ms [Q A H G I J K L B C E]
time 1999ms: Process A started using the CPU for 24ms burst [Q H G I J K L B C E]
time 2023ms: Process A completed a CPU burst; 6 bursts to go [Q H G I J K L B C E]
time 2023ms: Recalculated tau = 39ms for process A [Q H G I J K L B C E]
time 2023ms: Process A switching out of CPU; will block on I/O until time 2142ms [Q H G I J K L B C E]
time 2027ms: Process H started using the CPU for 100ms burst [Q G I J K L B C E]
time 2047ms: Process D (tau 83ms) completed I/O; added to ready queue [Q D G I J K L B C E]
time 2127ms: Process H completed a CPU burst; 80 bursts to go [Q D G I J K L B C E]
time 2127ms: Recalculated tau = 78ms for process H [Q D G I J K L B C E]
time 2127ms: Process H switching out of CPU; will block on I/O until time 2194ms [Q D G I J K L B C E]
time 2131ms: Process D started using the CPU for 90ms burst [Q G I J K L B C E]
time 2142ms: Process A (tau 39ms) completed I/O; added to ready queue [Q A G I J K L B C E]
time 2186ms: Process F (tau 35ms) completed I/O; added to ready queue [Q F A G I J K L B C E]
time 2194ms: Process H (tau 78ms) completed I/O; added to ready queue [Q F A H G I J K L B C E]
time 2221ms: Process D completed a CPU burst; 28 bursts to go [Q F A H G I J K L B C E]
time 2221ms: Recalculated tau = 87ms for process D [Q F A H G I J K L B C E]
time 2221ms: Process D switching out of CPU; will block on I/O until time 2225ms [Q F A H G I J K L B C E]
time 2225ms: Process F started using the CPU for 84ms burst [Q A H G I J K L B C E]
time 2225ms: Process D (tau 87ms) completed I/O; added to ready queue [Q A H D G I J K L B C E]
time 2309ms: Process F completed a CPU burst; 33 bursts to go [Q A H D G I J K L B C E]
time 2309ms: Recalculated tau = 60ms for process F [Q A H D G I J K L B C E]
time 2309ms: Process F switching out of CPU; will block on I/O until time 2406ms [Q A H D G I J K L B C E]
time 2313ms: Process A started using the CPU for 76ms burst [Q H D G I J K L B C E]
time 2389ms: Process A completed a CPU burst; 5 bursts to go [Q H D G I J K L B C E]
time 2389ms: Recalculated tau = 58ms for process A [Q H D G I J K L B C E]
time 2389ms: Process A switching out of CPU; will block on I/O until time 2419ms [Q H D G I J K L B C E]
time 2393ms: Process H started using the CPU for 32ms burst [Q D G I J K L B C E]
time 2406ms: Process F (tau 60ms) completed I/O; added to ready queue [Q F D G I J K L B C E]
time 2419ms: Process A (tau 58ms) completed I/O; added to ready queue [Q A F D G I J K L B C E]
time 2425ms: Process H completed a CPU burst; 79 bursts to go [Q A F D G I J K L B C E]
time 2425ms: Recalculated tau = 55ms for process H [Q A F D G I J K L B C E]
time 2425ms: Process H switching out of CPU; will block on I/O until time 2485ms [Q A F D G I J K L B C E]
time 2429ms: Process A started using the CPU for 122ms burst [Q F D G I J K L B C E]
time 2485ms: Process H (tau 55ms) completed I/O; added to ready queue [Q H F D G I J K L B C E]
time 2551ms: Process A completed a CPU burst; 4 bursts to go [Q H F D G I J K L B C E]
time 2551ms: Recalculated tau = 90ms for process A [Q H F D G I J K L B C E]
time 2551ms: Process A switching out of CPU; will block on I/O until time 2586ms [Q H F D G I J K L B C E]
time 2555ms: Process H started using the CPU for 174ms burst [Q F D G I J K L B C E]
time 2586ms: Process A (tau 90ms) completed I/O; added to ready queue [Q F D G A I J K L B C E]
time 2729ms: Process H completed a CPU burst; 78 bursts to go [Q F D G A I J K L B C E]
time 2729ms: Recalculated tau = 115ms for process H [Q F D G A I J K L B C E]
time 2729ms: Process H switching out of CPU; will block on I/O until time 2826ms [Q F D G A I J K L B C E]
time 2733ms: Process F started using the CPU for 26ms burst [Q D G A I J K L B C E]
time 2759ms: Process F completed a CPU burst; 32 bursts to go [Q D G A I J K L B C E]
time 2759ms: Recalculated tau = 43ms for process F [Q D G A I J K L B C E]
time 2759ms: Process F switching out of CPU; will block on I/O until time 2929ms [Q D G A I J K L B C E]
time 2763ms: Process D started using the CPU for 170ms burst [Q G A I J K L B C E]
time 2826ms: Process H (tau 115ms) completed I/O; added to ready queue [Q G A I J K L B H C E]
time 2929ms: Process F (tau 43ms) completed I/O; added to ready queue [Q F G A I J K L B H C E]
time 2933ms: Process D completed a CPU burst; 27 bursts to go [Q F G A I J K L B H C E]
time 2933ms: Recalculated tau = 129ms for process D [Q F G A I J K L B H C E]
time 2933ms: Process D switching out of CPU; will block on I/O until time 2993ms [Q F G A I J K L B H C E]
time 2937ms: Process F started using the CPU for 91ms burst [Q G A I J K L B H C E]
time 2993ms: Process D (tau 129ms) completed I/O; added to ready queue [Q G A I J K L B H C E D]
time 3028ms: Process F completed a CPU burst; 31 bursts to go [Q G A I J K L B H C E D]
time 3028ms: Recalculated tau = 67ms for process F [Q G A I J K L B H C E D]
time 3028ms: Process F switching out of CPU; will block on I/O until time 3065ms [Q G A I J K L B H C E D]
time 3032ms: Process G started using the CPU for 184ms burst [Q A I J K L B H C E D]
time 3065ms: Process F (tau 67ms) completed I/O; added to ready queue [Q F A I J K L B H C E D]
time 3216ms: Process G completed a CPU burst; 74 bursts to go [Q F A I J K L B H C E D]
time 3216ms: Recalculated tau = 136ms for process G [Q F A I J K L B H C E D]
time 3216ms: Process G switching out of CPU; will block on I/O until time 3250ms [Q F A I J K L B H C E D]
time 3220ms: Process F started using the CPU for 166ms burst [Q A I J K L B H C E D]
time 3250ms: Process G (tau 136ms) completed I/O; added to ready queue [Q A I J K L B H C E D G]
time 3386ms: Process F completed a CPU burst; 30 bursts to go [Q A I J K L B H C E D G]
time 3386ms: Recalculated tau = 117ms for process F [Q A I J K L B H C E D G]
time 3386ms: Process F switching out of CPU; will block on I/O until time 3447ms [Q A I J K L B H C E D G]
time 3390ms: Process A started using the CPU for 9ms burst [Q I J K L B H C E D G]
time 3399ms: Process A completed a CPU burst; 3 bursts to go [Q I J K L B H C E D G]
time 3399ms: Recalculated tau = 50ms for process A [Q I J K L B H C E D G]
time 3399ms: Process A switching out of CPU; will block on I/O until time 3469ms [Q I J K L B H C E D G]
time 3403ms: Process I started using the CPU for 190ms burst [Q J K L B H C E D G]
time 3447ms: Process F (tau 117ms) completed I/O; added to ready queue [Q J K L B H F C E D G]
time 3469ms: Process A (tau 50ms) completed I/O; added to ready queue [Q A J K L B H F C E D G]
time 3593ms: Process I completed a CPU burst; 62 bursts to go [Q A J K L B H F C E D G]
time 3593ms: Recalculated tau = 145ms for process I [Q A J K L B H F C E D G]
time 3593ms: Process I switching out of CPU; will block on I/O until time 3730ms [Q A J K L B H F C E D G]
time 3597ms: Process A started using the CPU for 62ms burst [Q J K L B H F C E D G]
time 3659ms: Process A completed a CPU burst; 2 bursts to go [Q J K L B H F C E D G]
time 3659ms: Recalculated tau = 56ms for process A [Q J K L B H F C E D G]
time 3659ms: Process A switching out of CPU; will block on I/O until time 3738ms [Q J K L B H F C E D G]
time 3663ms: Process J started using the CPU for 97ms burst [Q K L B H F C E D G]
time 3730ms: Process I (tau 145ms) completed I/O; added to ready queue [Q K L B H F C E D G I]
time 3738ms: Process A (tau 56ms) completed I/O; added to ready queue [Q A K L B H F C E D G I]
time 3760ms: Process J completed a CPU burst; 20 bursts to go [Q A K L B H F C E D G I]
time 3760ms: Recalculated tau = 99ms for process J [Q A K L B H F C E D G I]
time 3760ms: Process J switching out of CPU; will block on I/O until time 3853ms [Q A K L B H F C E D G I]
time 3764ms: Process A started using the CPU for 200ms burst [Q K L B H F C E D G I]
time 3853ms: Process J (tau 99ms) completed I/O; added to ready queue [Q J K L B H F C E D G I]
time 3964ms: Process A completed a CPU burst; 1 burst to go [Q J K L B H F C E D G I]
time 3964ms: Recalculated tau = 128ms for process A [Q J K L B H F C E D G I]
time 3964ms: Process A switching out of CPU; will block on I/O until time 3977ms [Q J K L B H F C E D G I]
time 3968ms: Process J started using the CPU for 39ms burst [Q K L B H F C E D G I]
time 3977ms: Process A (tau 128ms) completed I/O; added to ready queue [Q K L B H F C A E D G I]
time 4007ms: Process J completed a CPU burst; 19 bursts to go [Q K L B H F C A E D G I]
time 4007ms: Recalculated tau = 69ms for process J [Q K L B H F C A E D G I]
time 4007ms: Process J switching out of CPU; will block on I/O until time 4010ms [Q K L B H F C A E D G I]
time 4010ms: Process J (tau 69ms) completed I/O; added to ready queue [Q J L B H F C A E D G I]
time 4011ms: Process K started using the CPU for 37ms burst [Q J L B H F C A E D G I]
time 4048ms: Process K terminated [Q J L B H F C A E D G I]
time 4052ms: Process J started using the CPU for 137ms burst [Q L B H F C A E D G I]
time 4189ms: Process J completed a CPU burst; 18 bursts to go [Q L B H F C A E D G I]
time 4189ms: Recalculated tau = 103ms for process J [Q L B H F C A E D G I]
time 4189ms: Process J switching out of CPU; will block on I/O until time 4210ms [Q L B H F C A E D G I]
time 4193ms: Process L started using the CPU for 133ms burst [Q B H F C A E D G I]
time 4210ms: Process J (tau 103ms) completed I/O; added to ready queue [Q B J H F C A E D G I]
time 4326ms: Process L completed a CPU burst; 2 bursts to go [Q B J H F C A E D G I]
time 4326ms: Recalculated tau = 117ms for process L [Q B J H F C A E D G I]
time 4326ms: Process L switching out of CPU; will block on I/O until time 4458ms [Q B J H F C A E D G I]
time 4330ms: Process B started using the CPU for 198ms burst [Q J H F C A E D G I]
time 4458ms: Process L (tau 117ms) completed I/O; added to ready queue [Q J H F L C A E D G I]
time 4528ms: Process B completed a CPU burst; 19 bursts to go [Q J H F L C A E D G I]
time 4528ms: Recalculated tau = 151ms for process B [Q J H F L C A E D G I]
time 4528ms: Process B switching out of CPU; will block on I/O until time 4643ms [Q J H F L C A E D G I]
time 4532ms: Process J started using the CPU for 189ms burst [Q H F L C A E D G I]
time 4643ms: Process B (tau 151ms) completed I/O; added to ready queue [Q H F L C A E D G I B]
time 4721ms: Process J completed a CPU burst; 17 bursts to go [Q H F L C A E D G I B]
time 4721ms: Recalculated tau = 146ms for process J [Q H F L C A E D G I B]
time 4721ms: Process J switching out of CPU; will block on I/O until time 4886ms [Q H F L C A E D G I B]
time 4725ms: Process H started using the CPU for 142ms burst [Q F L C A E D G I B]
time 4867ms: Process H completed a CPU burst; 77 bursts to go [Q F L C A E D G I B]
time 4867ms: Recalculated tau = 129ms for process H [Q F L C A E D G I B]
time 4867ms: Process H switching out of CPU; will block on I/O until time 4947ms [Q F L C A E D G I B]
time 4871ms: Process F started using the CPU for 67ms burst [Q L C A E D G I B]
time 4886ms: Process J (tau 146ms) completed I/O; added to ready queue [Q L C A E D G I J B]
time 4938ms: Process F completed a CPU burst; 29 bursts to go [Q L C A E D G I J B]
time 4938ms: Recalculated tau = 92ms for process F [Q L C A E D G I J B]
time 4938ms: Process F switching out of CPU; will block on I/O until time 5131ms [Q L C A E D G I J B]
time 4942ms: Process L started using the CPU for 71ms burst [Q C A E D G I J B]
time 4947ms: Process H (tau 129ms) completed I/O; added to ready queue [Q C A E D H G I J B]
time 5013ms: Process L completed a CPU burst; 1 burst to go [Q C A E D H G I J B]
time 5013ms: Recalculated tau = 94ms for process L [Q C A E D H G I J B]
time 5013ms: Process L switching out of CPU; will block on I/O until time 5083ms [Q C A E D H G I J B]
time 5017ms: Process C started using the CPU for 9ms burst [Q A E D H G I J B]
time 5026ms: Process C completed a CPU burst; 79 bursts to go [Q A E D H G I J B]
time 5026ms: Recalculated tau = 64ms for process C [Q A E D H G I J B]
time 5026ms: Process C switching out of CPU; will block on I/O until time 5066ms [Q A E D H G I J B]
time 5030ms: Process A started using the CPU for 197ms burst [Q E D H G I J B]
time 5066ms: Process C (tau 64ms) completed I/O; added to ready queue [Q C E D H G I J B]
time 5083ms: Process L (tau 94ms) completed I/O; added to ready queue [Q C L E D H G I J B]
time 5131ms: Process F (tau 92ms) completed I/O; added to ready queue [Q C F L E D H G I J B]
time 5227ms: Process A terminated [Q C F L E D H G I J B]
time 5231ms: Process C started using the CPU for 4ms burst [Q F L E D H G I J B]
time 5235ms: Process C completed a CPU burst; 78 bursts to go [Q F L E D H G I J B]
time 5235ms: Recalculated tau = 34ms for process C [Q F L E D H G I J B]
time 5235ms: Process C switching out of CPU; will block on I/O until time 5285ms [Q F L E D H G I J B]
time 5239ms: Process F started using the CPU for 78ms burst [Q L E D H G I J B]
time 5285ms: Process C (tau 34ms) completed I/O; added to ready queue [Q C L E D H G I J B]
time 5317ms: Process F completed a CPU burst; 28 bursts to go [Q C L E D H G I J B]
time 5317ms: Recalculated tau = 85ms for process F [Q C L E D H G I J B]
time 5317ms: Process F switching out of CPU; will block on I/O until time 5410ms [Q C L E D H G I J B]
time 5321ms: Process C started using the CPU for 149ms burst [Q L E D H G I J B]
time 5410ms: Process F (tau 85ms) completed I/O; added to ready queue [Q F L E D H G I J B]
time 5470ms: Process C completed a CPU burst; 77 bursts to go [Q F L E D H G I J B]
time 5470ms: Recalculated tau = 92ms for process C [Q F L E D H G I J B]
time 5470ms: Process C switching out of CPU; will block on I/O until time 5553ms [Q F L E D H G I J B]
time 5474ms: Process F started using the CPU for 38ms burst [Q L E D H G I J B]
time 5512ms: Process F completed a CPU burst; 27 bursts to go [Q L E D H G I J B]
time 5512ms: Recalculated tau = 62ms for process F [Q L E D H G I J B]
time 5512ms: Process F switching out of CPU; will block on I/O until time 5525ms [Q L E D H G I J B]
time 5516ms: Process L started using the CPU for 117ms burst [Q E D H G I J B]
time 5525ms: Process F (tau 62ms) completed I/O; added to ready queue [Q F E D H G I J B]
time 5553ms: Process C (tau 92ms) completed I/O; added to ready queue [Q F C E D H G I J B]
time 5633ms: Process L terminated [Q F C E D H G I J B]
time 5637ms: Process F started using the CPU for 120ms burst [Q C E D H G I J B]
time 5757ms: Process F completed a CPU burst; 26 bursts to go [Q C E D H G I J B]
time 5757ms: Recalculated tau = 91ms for process F [Q C E D H G I J B]
time 5757ms: Process F switching out of CPU; will block on I/O until time 5879ms [Q C E D H G I J B]
time 5761ms: Process C started using the CPU for 52ms burst [Q E D H G I J B]
time 5813ms: Process C completed a CPU burst; 76 bursts to go [Q E D H G I J B]
time 5813ms: Recalculated tau = 72ms for process C [Q E D H G I J B]
time 5813ms: Process C switching out of CPU; will block on I/O until time 5818ms [Q E D H G I J B]
time 5817ms: Process E started using the CPU for 35ms burst [Q D H G I J B]
time 5818ms: Process C (tau 72ms) completed I/O; added to ready queue [Q C D H G I J B]
time 5852ms: Process E completed a CPU burst; 21 bursts to go [Q C D H G I J B]
time 5852ms: Recalculated tau = 82ms for process E [Q C D H G I J B]
time 5852ms: Process E switching out of CPU; will block on I/O until time 5925ms [Q C D H G I J B]
time 5856ms: Process C started using the CPU for 23ms burst [Q D H G I J B]
time 5879ms: Process C completed a CPU burst; 75 bursts to go [Q D H G I J B]
time 5879ms: Recalculated tau = 48ms for process C [Q D H G I J B]
time 5879ms: Process C switching out of CPU; will block on I/O until time 6075ms [Q D H G I J B]
time 5879ms: Process F (tau 91ms) completed I/O; added to ready queue [Q F D H G I J B]
time 5883ms: Process F started using the CPU for 62ms burst [Q D H G I J B]
time 5925ms: Process E (tau 82ms) completed I/O; added to ready queue [Q E D H G I J B]
time 5945ms: Process F completed a CPU burst; 25 bursts to go [Q E D H G I J B]
time 5945ms: Recalculated tau = 77ms for process F [Q E D H G I J B]
time 5945ms: Process F switching out of CPU; will block on I/O until time 6052ms [Q E D H G I J B]
time 5949ms: Process E started using the CPU for 44ms burst [Q D H G I J B]
time 5993ms: Process E completed a CPU burst; 20 bursts to go [Q D H G I J B]
time 5993ms: Recalculated tau = 63ms for process E [Q D H G I J B]
time 5993ms: Process E switching out of CPU; will block on I/O until time 6019ms [Q D H G I J B]
time 5997ms: Process D started using the CPU for 154ms burst [Q H G I J B]
time 6019ms: Process E (tau 63ms) completed I/O; added to ready queue [Q E H G I J B]
time 6052ms: Process F (tau 77ms) completed I/O; added to ready queue [Q E F H G I J B]
time 6075ms: Process C (tau 48ms) completed I/O; added to ready queue [Q C E F H G I J B]
time 6151ms: Process D completed a CPU burst; 26 bursts to go [Q C E F H G I J B]
time 6151ms: Recalculated tau = 142ms for process D [Q C E F H G I J B]
time 6151ms: Process D switching out of CPU; will block on I/O until time 6189ms [Q C E F H G I J B]
time 6155ms: Process C started using the CPU for 76ms burst [Q E F H G I J B]
time 6189ms: Process D (tau 142ms) completed I/O; added to ready queue [Q E F H G D I J B]
time 6231ms: Process C completed a CPU burst; 74 bursts to go [Q E F H G D I J B]
time 6231ms: Recalculated tau = 62ms for process C [Q E F H G D I J B]
time 6231ms: Process C switching out of CPU; will block on I/O until time 6306ms [Q E F H G D I J B]
time 6235ms: Process E started using the CPU for 27ms burst [Q F H G D I J B]
time 6262ms: Process E completed a CPU burst; 19 bursts to go [Q F H G D I J B]
time 6262ms: Recalculated tau = 45ms for process E [Q F H G D I J B]
time 6262ms: Process E switching out of CPU; will block on I/O until time 6387ms [Q F H G D I J B]
time 6266ms: Process F started using the CPU for 40ms burst [Q H G D I J B]
time 6306ms: Process F completed a CPU burst; 24 bursts to go [Q H G D I J B]
time 6306ms: Recalculated tau = 59ms for process F [Q H G D I J B]
time 6306ms: Process F switching out of CPU; will block on I/O until time 6434ms [Q H G D I J B]
time 6306ms: Process C (tau 62ms) completed I/O; added to ready queue [Q C H G D I J B]
time 6310ms: Process C started using the CPU for 50ms burst [Q H G D I J B]
time 6360ms: Process C completed a CPU burst; 73 bursts to go [Q H G D I J B]
time 6360ms: Recalculated tau = 56ms for process C [Q H G D I J B]
time 6360ms: Process C switching out of CPU; will block on I/O until time 6374ms [Q H G D I J B]
time 6364ms: Process H started using the CPU for 77ms burst [Q G D I J B]
time 6374ms: Process C (tau 56ms) completed I/O; added to ready queue [Q C G D I J B]
time 6387ms: Process E (tau 45ms) completed I/O; added to ready queue [Q E C G D I J B]
time 6434ms: Process F (tau 59ms) completed I/O; added to ready queue [Q E C F G D I J B]
time 6441ms: Process H completed a CPU burst; 76 bursts to go [Q E C F G D I J B]
time 6441ms: Recalculated tau = 103ms for process H [Q E C F G D I J B]
time 6441ms: Process H switching out of CPU; will block on I/O until time 6474ms [Q E C F G D I J B]
time 6445ms: Process E started using the CPU for 171ms burst [Q C F G D I J B]
time 6474ms: Process H (tau 103ms) completed I/O; added to ready queue [Q C F H G D I J B]
time 6616ms: Process E completed a CPU burst; 18 bursts to go [Q C F H G D I J B]
time 6616ms: Recalculated tau = 108ms for process E [Q C F H G D I J B]
time 6616ms: Process E switching out of CPU; will block on I/O until time 6647ms [Q C F H G D I J B]
time 6620ms: Process C started using the CPU for 24ms burst [Q F H G D I J B]
time 6644ms: Process C completed a CPU burst; 72 bursts to go [Q F H G D I J B]
time 6644ms: Recalculated tau = 40ms for process C [Q F H G D I J B]
time 6644ms: Process C switching out of CPU; will block on I/O until time 6671ms [Q F H G D I J B]
time 6647ms: Process E (tau 108ms) completed I/O; added to ready queue [Q H E G D I J B]
time 6648ms: Process F started using the CPU for 167ms burst [Q H E G D I J B]
time 6671ms: Process C (tau 40ms) completed I/O; added to ready queue [Q C H E G D I J B]
time 6815ms: Process F completed a CPU burst; 23 bursts to go [Q C H E G D I J B]
time 6815ms: Recalculated tau = 113ms for process F [Q C H E G D I J B]
time 6815ms: Process F switching out of CPU; will block on I/O until time 6891ms [Q C H E G D I J B]
time 6819ms: Process C started using the CPU for 1ms burst [Q H E G D I J B]
time 6820ms: Process C completed a CPU burst; 71 bursts to go [Q H E G D I J B]
time 6820ms: Recalculated tau = 21ms for process C [Q H E G D I J B]
time 6820ms: Process C switching out of CPU; will block on I/O until time 6957ms [Q H E G D I J B]
time 6824ms: Process H started using the CPU for 109ms burst [Q E G D I J B]
time 6891ms: Process F (tau 113ms) completed I/O; added to ready queue [Q E F G D I J B]
time 6933ms: Process H completed a CPU burst; 75 bursts to go [Q E F G D I J B]
time 6933ms: Recalculated tau = 106ms for process H [Q E F G D I J B]
time 6933ms: Process H switching out of CPU; will block on I/O until time 7032ms [Q E F G D I J B]
time 6937ms: Process E started using the CPU for 3ms burst [Q F G D I J B]
time 6940ms: Process E completed a CPU burst; 17 bursts to go [Q F G D I J B]
time 6940ms: Recalculated tau = 56ms for process E [Q F G D I J B]
time 6940ms: Process E switching out of CPU; will block on I/O until time 7072ms [Q F G D I J B]
time 6944ms: Process F started using the CPU for 45ms burst [Q G D I J B]
time 6957ms: Process C (tau 21ms) completed I/O; added to ready queue [Q C G D I J B]
time 6989ms: Process F completed a CPU burst; 22 bursts to go [Q C G D I J B]
time 6989ms: Recalculated tau = 79ms for process F [Q C G D I J B]
time 6989ms: Process F switching out of CPU; will block on I/O until time 7085ms [Q C G D I J B]
time 6993ms: Process C started using the CPU for 61ms burst [Q G D I J B]
time 7032ms: Process H (tau 106ms) completed I/O; added to ready queue [Q H G D I J B]
time 7054ms: Process C completed a CPU burst; 70 bursts to go [Q H G D I J B]
time 7054ms: Recalculated tau = 41ms for process C [Q H G D I J B]
time 7054ms: Process C switching out of CPU; will block on I/O until time 7208ms [Q H G D I J B]
time 7058ms: Process H started using the CPU for 18ms burst [Q G D I J B]
time 7072ms: Process E (tau 56ms) completed I/O; added to ready queue [Q E G D I J B]
time 7076ms: Process H completed a CPU burst; 74 bursts to go [Q E G D I J B]
time 7076ms: Recalculated tau = 62ms for process H [Q E G D I J B]
time 7076ms: Process H switching out of CPU; will block on I/O until time 7181ms [Q E G D I J B]
time 7080ms: Process E started using the CPU for 107ms burst [Q G D I J B]
time 7085ms: Process F (tau 79ms) completed I/O; added to ready queue [Q F G D I J B]
time 7181ms: Process H (tau 62ms) completed I/O; added to ready queue [Q H F G D I J B]
time 7187ms: Process E completed a CPU burst; 16 bursts to go [Q H F G D I J B]
time 7187ms: Recalculated tau = 82ms for process E [Q H F G D I J B]
time 7187ms: Process E switching out of CPU; will block on I/O until time 7206ms [Q H F G D I J B]
time 7191ms: Process H started using the CPU for 87ms burst [Q F G D I J B]
time 7206ms: Process E (tau 82ms) completed I/O; added to ready queue [Q F E G D I J B]
time 7208ms: Process C (tau 41ms) completed I/O; added to ready queue [Q C F E G D I J B]
time 7278ms: Process H completed a CPU burst; 73 bursts to go [Q C F E G D I J B]
time 7278ms: Recalculated tau = 75ms for process H [Q C F E G D I J B]
time 7278ms: Process H switching out of CPU; will block on I/O until time 7324ms [Q C F E G D I J B]
time 7282ms: Process C started using the CPU for 46ms burst [Q F E G D I J B]
time 7324ms: Process H (tau 75ms) completed I/O; added to ready queue [Q H F E G D I J B]
time 7328ms: Process C completed a CPU burst; 69 bursts to go [Q H F E G D I J B]
time 7328ms: Recalculated tau = 44ms for process C [Q H F E G D I J B]
time 7328ms: Process C switching out of CPU; will block on I/O until time 7374ms [Q H F E G D I J B]
time 7332ms: Process H started using the CPU for 199ms burst [Q F E G D I J B]
time 7374ms: Process C (tau 44ms) completed I/O; added to ready queue [Q C F E G D I J B]
time 7531ms: Process H completed a CPU burst; 72 bursts to go [Q C F E G D I J B]
time 7531ms: Recalculated tau = 137ms for process H [Q C F E G D I J B]
time 7531ms: Process H switching out of CPU; will block on I/O until time 7570ms [Q C F E G D I J B]
time 7535ms: Process C started using the CPU for 56ms burst [Q F E G D I J B]
time 7570ms: Process H (tau 137ms) completed I/O; added to ready queue [Q F E G H D I J B]
time 7591ms: Process C completed a CPU burst; 68 bursts to go [Q F E G H D I J B]
time 7591ms: Recalculated tau = 50ms for process C [Q F E G H D I J B]
time 7591ms: Process C switching out of CPU; will block on I/O until time 7595ms [Q F E G H D I J B]
time 7595ms: Process F started using the CPU for 96ms burst [Q E G H D I J B]
time 7595ms: Process C (tau 50ms) completed I/O; added to ready queue [Q C E G H D I J B]
time 7691ms: Process F completed a CPU burst; 21 bursts to go [Q C E G H D I J B]
time 7691ms: Recalculated tau = 88ms for process F [Q C E G H D I J B]
time 7691ms: Process F switching out of CPU; will block on I/O until time 7876ms [Q C E G H D I J B]
time 7695ms: Process C started using the CPU for 25ms burst [Q E G H D I J B]
time 7720ms: Process C completed a CPU burst; 67 bursts to go [Q E G H D I J B]
time 7720ms: Recalculated tau = 38ms for process C [Q E G H D I J B]
time 7720ms: Process C switching out of CPU; will block on I/O until time 7764ms [Q E G H D I J B]
time 7724ms: Process E started using the CPU for 111ms burst [Q G H D I J B]
time 7764ms: Process C (tau 38ms) completed I/O; added to ready queue [Q C G H D I J B]
time 7835ms: Process E completed a CPU burst; 15 bursts to go [Q C G H D I J B]
time 7835ms: Recalculated tau = 97ms for process E [Q C G H D I J B]
time 7835ms: Process E switching out of CPU; will block on I/O until time 7868ms [Q C G H D I J B]
time 7839ms: Process C started using the CPU for 5ms burst [Q G H D I J B]
time 7844ms: Process C completed a CPU burst; 66 bursts to go [Q G H D I J B]
time 7844ms: Recalculated tau = 22ms for process C [Q G H D I J B]
time 7844ms: Process C switching out of CPU; will block on I/O until time 7954ms [Q G H D I J B]
time 7848ms: Process G started using the CPU for 82ms burst [Q H D I J B]
time 7868ms: Process E (tau 97ms) completed I/O; added to ready queue [Q E H D I J B]
time 7876ms: Process F (tau 88ms) completed I/O; added to ready queue [Q F E H D I J B]
time 7930ms: Process G completed a CPU burst; 73 bursts to go [Q F E H D I J B]
time 7930ms: Recalculated tau = 109ms for process G [Q F E H D I J B]
time 7930ms: Process G switching out of CPU; will block on I/O until time 8010ms [Q F E H D I J B]
time 7934ms: Process F started using the CPU for 37ms burst [Q E H D I J B]
time 7954ms: Process C (tau 22ms) completed I/O; added to ready queue [Q C E H D I J B]
time 7971ms: Process F completed a CPU burst; 20 bursts to go [Q C E H D I J B]
time 7971ms: Recalculated tau = 63ms for process F [Q C E H D I J B]
time 7971ms: Process F switching out of CPU; will block on I/O until time 8032ms [Q C E H D I J B]
time 7975ms: Process C started using the CPU for 9ms burst [Q E H D I J B]
time 7984ms: Process C completed a CPU burst; 65 bursts to go [Q E H D I J B]
time 7984ms: Recalculated tau = 16ms for process C [Q E H D I J B]
time 7984ms: Process C switching out of CPU; will block on I/O until time 7992ms [Q E H D I J B]
time 7988ms: Process E started using the CPU for 11ms burst [Q H D I J B]
time 7992ms: Process C (tau 16ms) completed I/O; added to ready queue [Q C H D I J B]
time 7999ms: Process E completed a CPU burst; 14 bursts to go [Q C H D I J B]
time 7999ms: Recalculated tau = 54ms for process E [Q C H D I J B]
time 7999ms: Process E switching out of CPU; will block on I/O until time 8079ms [Q C H D I J B]
time 8003ms: Process C started using the CPU for 32ms burst [Q H D I J B]
time 8010ms: Process G (tau 109ms) completed I/O; added to ready queue [Q G H D I J B]
time 8032ms: Process F (tau 63ms) completed I/O; added to ready queue [Q F G H D I J B]
time 8035ms: Process C completed a CPU burst; 64 bursts to go [Q F G H D I J B]
time 8035ms: Recalculated tau = 24ms for process C [Q F G H D I J B]
time 8035ms: Process C switching out of CPU; will block on I/O until time 8149ms [Q F G H D I J B]
time 8039ms: Process F started using the CPU for 15ms burst [Q G H D I J B]
time 8054ms: Process F completed a CPU burst; 19 bursts to go [Q G H D I J B]
time 8054ms: Recalculated tau = 39ms for process F [Q G H D I J B]
time 8054ms: Process F switching out of CPU; will block on I/O until time 8080ms [Q G H D I J B]
time 8058ms: Process G started using the CPU for 6ms burst [Q H D I J B]
time 8064ms: Process G completed a CPU burst; 72 bursts to go [Q H D I J B]
time 8064ms: Recalculated tau = 58ms for process G [Q H D I J B]
time 8064ms: Process G switching out of CPU; will block on I/O until time 8082ms [Q H D I J B]
time 8068ms: Process H started using the CPU for 90ms burst [Q D I J B]
time 8079ms: Process E (tau 54ms) completed I/O; added to ready queue [Q E D I J B]
time 8080ms: Process F (tau 39ms) completed I/O; added to ready queue [Q F E D I J B]
time 8082ms: Process G (tau 58ms) completed I/O; added to ready queue [Q F E G D I J B]
time 8149ms: Process C (tau 24ms) completed I/O; added to ready queue [Q C F E G D I J B]
time 8158ms: Process H completed a CPU burst; 71 bursts to go [Q C F E G D I J B]
time 8158ms: Recalculated tau = 114ms for process H [Q C F E G D I J B]
time 8158ms: Process H switching out of CPU; will block on I/O until time 8161ms [Q C F E G D I J B]
time 8161ms: Process H (tau 114ms) completed I/O; added to ready queue [Q F E G H D I J B]
time 8162ms: Process C started using the CPU for 111ms burst [Q F E G H D I J B]
time 8273ms: Process C completed a CPU burst; 63 bursts to go [Q F E G H D I J B]
time 8273ms: Recalculated tau = 68ms for process C [Q F E G H D I J B]
time 8273ms: Process C switching out of CPU; will block on I/O until time 8287ms [Q F E G H D I J B]
time 8277ms: Process F started using the CPU for 62ms burst [Q E G H D I J B]
time 8287ms: Process C (tau 68ms) completed I/O; added to ready queue [Q E G C H D I J B]
time 8339ms: Process F completed a CPU burst; 18 bursts to go [Q E G C H D I J B]
time 8339ms: Recalculated tau = 51ms for process F [Q E G C H D I J B]
time 8339ms: Process F switching out of CPU; will block on I/O until time 8421ms [Q E G C H D I J B]
time 8343ms: Process E started using the CPU for 28ms burst [Q G C H D I J B]
time 8371ms: Process E completed a CPU burst; 13 bursts to go [Q G C H D I J B]
time 8371ms: Recalculated tau = 41ms for process E [Q G C H D I J B]
time 8371ms: Process E switching out of CPU; will block on I/O until time 8379ms [Q G C H D I J B]
time 8375ms: Process G started using the CPU for 55ms burst [Q C H D I J B]
time 8379ms: Process E (tau 41ms) completed I/O; added to ready queue [Q E C H D I J B]
time 8421ms: Process F (tau 51ms) completed I/O; added to ready queue [Q E F C H D I J B]
time 8430ms: Process G completed a CPU burst; 71 bursts to go [Q E F C H D I J B]
time 8430ms: Recalculated tau = 57ms for process G [Q E F C H D I J B]
time 8430ms: Process G switching out of CPU; will block on I/O until time 8574ms [Q E F C H D I J B]
time 8434ms: Process E started using the CPU for 137ms burst [Q F C H D I J B]
time 8571ms: Process E completed a CPU burst; 12 bursts to go [Q F C H D I J B]
time 8571ms: Recalculated tau = 89ms for process E [Q F C H D I J B]
time 8571ms: Process E switching out of CPU; will block on I/O until time 8628ms [Q F C H D I J B]
time 8574ms: Process G (tau 57ms) completed I/O; added to ready queue [Q G C H D I J B]
time 8575ms: Process F started using the CPU for 83ms burst [Q G C H D I J B]
time 8628ms: Process E (tau 89ms) completed I/O; added to ready queue [Q G C E H D I J B]
time 8658ms: Process F completed a CPU burst; 17 bursts to go [Q G C E H D I J B]
time 8658ms: Recalculated tau = 67ms for process F [Q G C E H D I J B]
time 8658ms: Process F switching out of CPU; will block on I/O until time 8693ms [Q G C E H D I J B]
time 8662ms: Process G started using the CPU for 97ms burst [Q C E H D I J B]
time 8693ms: Process F (tau 67ms) completed I/O; added to ready queue [Q F C E H D I J B]
time 8759ms: Process G completed a CPU burst; 70 bursts to go [Q F C E H D I J B]
time 8759ms: Recalculated tau = 77ms for process G [Q F C E H D I J B]
time 8759ms: Process G switching out of CPU; will block on I/O until time 8823ms [Q F C E H D I J B]
time 8763ms: Process F started using the CPU for 165ms burst [Q C E H D I J B]
time 8823ms: Process G (tau 77ms) completed I/O; added to ready queue [Q C G E H D I J B]
time 8928ms: Process F completed a CPU burst; 16 bursts to go [Q C G E H D I J B]
time 8928ms: Recalculated tau = 116ms for process F [Q C G E H D I J B]
time 8928ms: Process F switching out of CPU; will block on I/O until time 9005ms [Q C G E H D I J B]
time 8932ms: Process C started using the CPU for 45ms burst [Q G E H D I J B]
time 8977ms: Process C completed a CPU burst; 62 bursts to go [Q G E H D I J B]
time 8977ms: Recalculated tau = 57ms for process C [Q G E H D I J B]
time 8977ms: Process C switching out of CPU; will block on I/O until time 8988ms [Q G E H D I J B]
time 8981ms: Process G started using the CPU for 25ms burst [Q E H D I J B]
time 8988ms: Process C (tau 57ms) completed I/O; added to ready queue [Q C E H D I J B]
time 9005ms: Process F (tau 116ms) completed I/O; added to ready queue [Q C E H F D I J B]
time 9006ms: Process G completed a CPU burst; 69 bursts to go [Q C E H F D I J B]
time 9006ms: Recalculated tau = 51ms for process G [Q C E H F D I J B]
time 9006ms: Process G switching out of CPU; will block on I/O until time 9090ms [Q C E H F D I J B]
time 9010ms: Process C started using the CPU for 67ms burst [Q E H F D I J B]
time 9077ms: Process C completed a CPU burst; 61 bursts to go [Q E H F D I J B]
time 9077ms: Recalculated tau = 62ms for process C [Q E H F D I J B]
time 9077ms: Process C switching out of CPU; will block on I/O until time 9141ms [Q E H F D I J B]
time 9081ms: Process E started using the CPU for 124ms burst [Q H F D I J B]
time 9090ms: Process G (tau 51ms) completed I/O; added to ready queue [Q G H F D I J B]
time 9141ms: Process C (tau 62ms) completed I/O; added to ready queue [Q G C H F D I J B]
time 9205ms: Process E completed a CPU burst; 11 bursts to go [Q G C H F D I J B]
time 9205ms: Recalculated tau = 107ms for process E [Q G C H F D I J B]
time 9205ms: Process E switching out of CPU; will block on I/O until time 9282ms [Q G C H F D I J B]
time 9209ms: Process G started using the CPU for 37ms burst [Q C H F D I J B]
time 9246ms: Process G completed a CPU burst; 68 bursts to go [Q C H F D I J B]
time 9246ms: Recalculated tau = 44ms for process G [Q C H F D I J B]
time 9246ms: Process G switching out of CPU; will block on I/O until time 9251ms [Q C H F D I J B]
time 9250ms: Process C started using the CPU for 60ms burst [Q H F D I J B]
time 9251ms: Process G (tau 44ms) completed I/O; added to ready queue [Q G H F D I J B]
time 9282ms: Process E (tau 107ms) completed I/O; added to ready queue [Q G E H F D I J B]
time 9310ms: Process C completed a CPU burst; 60 bursts to go [Q G E H F D I J B]
time 9310ms: Recalculated tau = 61ms for process C [Q G E H F D I J B]
time 9310ms: Process C switching out of CPU; will block on I/O until time 9505ms [Q G E H F D I J B]
time 9314ms: Process G started using the CPU for 10ms burst [Q E H F D I J B]
time 9324ms: Process G completed a CPU burst; 67 bursts to go [Q E H F D I J B]
time 9324ms: Recalculated tau = 27ms for process G [Q E H F D I J B]
time 9324ms: Process G switching out of CPU; will block on I/O until time 9332ms [Q E H F D I J B]
time 9328ms: Process E started using the CPU for 108ms burst [Q H F D I J B]
time 9332ms: Process G (tau 27ms) completed I/O; added to ready queue [Q G H F D I J B]
time 9436ms: Process E completed a CPU burst; 10 bursts to go [Q G H F D I J B]
time 9436ms: Recalculated tau = 108ms for process E [Q G H F D I J B]
time 9436ms: Process E switching out of CPU; will block on I/O until time 9555ms [Q G H F D I J B]
time 9440ms: Process G started using the CPU for 189ms burst [Q H F D I J B]
time 9505ms: Process C (tau 61ms) completed I/O; added to ready queue [Q C H F D I J B]
time 9555ms: Process E (tau 108ms) completed I/O; added to ready queue [Q C E H F D I J B]
time 9629ms: Process G completed a CPU burst; 66 bursts to go [Q C E H F D I J B]
time 9629ms: Recalculated tau = 108ms for process G [Q C E H F D I J B]
time 9629ms: Process G switching out of CPU; will block on I/O until time 9679ms [Q C E H F D I J B]
time 9633ms: Process C started using the CPU for 54ms burst [Q E H F D I J B]
time 9679ms: Process G (tau 108ms) completed I/O; added to ready queue [Q E G H F D I J B]
time 9687ms: Process C completed a CPU burst; 59 bursts to go [Q E G H F D I J B]
time 9687ms: Recalculated tau = 58ms for process C [Q E G H F D I J B]
time 9687ms: Process C switching out of CPU; will block on I/O until time 9784ms [Q E G H F D I J B]
time 9691ms: Process E started using the CPU for 110ms burst [Q G H F D I J B]
time 9784ms: Process C (tau 58ms) completed I/O; added to ready queue [Q C G H F D I J B]
time 9801ms: Process E completed a CPU burst; 9 bursts to go [Q C G H F D I J B]
time 9801ms: Recalculated tau = 109ms for process E [Q C G H F D I J B]
time 9801ms: Process E switching out of CPU; will block on I/O until time 9960ms [Q C G H F D I J B]
time 9805ms: Process C started using the CPU for 126ms burst [Q G H F D I J B]
time 9931ms: Process C completed a CPU burst; 58 bursts to go [Q G H F D I J B]
time 9931ms: Recalculated tau = 92ms for process C [Q G H F D I J B]
time 9931ms: Process C switching out of CPU; will block on I/O until time 10131ms [Q G H F D I J B]
time 9935ms: Process G started using the CPU for 134ms burst [Q H F D I J B]
time 9960ms: Process E (tau 109ms) completed I/O; added to ready queue [Q E H F D I J B]
time 10069ms: Process G completed a CPU burst; 65 bursts to go [Q E H F D I J B]
time 10069ms: Recalculated tau = 121ms for process G [Q E H F D I J B]
time 10069ms: Process G switching out of CPU; will block on I/O until time 10104ms [Q E H F D I J B]
time 10073ms: Process E started using the CPU for 77ms burst [Q H F D I J B]
time 10104ms: Process G (tau 121ms) completed I/O; added to ready queue [Q H F G D I J B]
time 10131ms: Process C (tau 92ms) completed I/O; added to ready queue [Q C H F G D I J B]
time 10150ms: Process E completed a CPU burst; 8 bursts to go [Q C H F G D I J B]
time 10150ms: Recalculated tau = 93ms for process E [Q C H F G D I J B]
time 10150ms: Process E switching out of CPU; will block on I/O until time 10174ms [Q C H F G D I J B]
time 10154ms: Process C started using the CPU for 168ms burst [Q H F G D I J B]
time 10174ms: Process E (tau 93ms) completed I/O; added to ready queue [Q E H F G D I J B]
time 10322ms: Process C completed a CPU burst; 57 bursts to go [Q E H F G D I J B]
time 10322ms: Recalculated tau = 130ms for process C [Q E H F G D I J B]
time 10322ms: Process C switching out of CPU; will block on I/O until time 10374ms [Q E H F G D I J B]
time 10326ms: Process E started using the CPU for 187ms burst [Q H F G D I J B]
time 10374ms: Process C (tau 130ms) completed I/O; added to ready queue [Q H F G C D I J B]
time 10513ms: Process E completed a CPU burst; 7 bursts to go [Q H F G C D I J B]
time 10513ms: Recalculated tau = 140ms for process E [Q H F G C D I J B]
time 10513ms: Process E switching out of CPU; will block on I/O until time 10577ms [Q H F G C D I J B]
time 10517ms: Process H started using the CPU for 2ms burst [Q F G C D I J B]
time 10519ms: Process H completed a CPU burst; 70 bursts to go [Q F G C D I J B]
time 10519ms: Recalculated tau = 58ms for process H [Q F G C D I J B]
time 10519ms: Process H switching out of CPU; will block on I/O until time 10617ms [Q F G C D I J B]
time 10523ms: Process F started using the CPU for 7ms burst [Q G C D I J B]
time 10530ms: Process F completed a CPU burst; 15 bursts to go [Q G C D I J B]
time 10530ms: Recalculated tau = 62ms for process F [Q G C D I J B]
time 10530ms: Process F switching out of CPU; will block on I/O until time 10548ms [Q G C D I J B]
time 10534ms: Process G started using the CPU for 25ms burst [Q C D I J B]
time 10548ms: Process F (tau 62ms) completed I/O; added to ready queue [Q F C D I J B]
time 10559ms: Process G completed a CPU burst; 64 bursts to go [Q F C D I J B]
time 10559ms: Recalculated tau = 73ms for process G [Q F C D I J B]
time 10559ms: Process G switching out of CPU; will block on I/O until time 10642ms [Q F C D I J B]
time 10563ms: Process F started using the CPU for 103ms burst [Q C D I J B]
time 10577ms: Process E (tau 140ms) completed I/O; added to ready queue [Q C E D I J B]
time 10617ms: Process H (tau 58ms) completed I/O; added to ready queue [Q H C E D I J B]
time 10642ms: Process G (tau 73ms) completed I/O; added to ready queue [Q H G C E D I J B]
time 10666ms: Process F completed a CPU burst; 14 bursts to go [Q H G C E D I J B]
time 10666ms: Recalculated tau = 83ms for process F [Q H G C E D I J B]
time 10666ms: Process F switching out of CPU; will block on I/O until time 10846ms [Q H G C E D I J B]
time 10670ms: Process H started using the CPU for 19ms burst [Q G C E D I J B]
time 10689ms: Process H completed a CPU burst; 69 bursts to go [Q G C E D I J B]
time 10689ms: Recalculated tau = 39ms for process H [Q G C E D I J B]
time 10689ms: Process H switching out of CPU; will block on I/O until time 10834ms [Q G C E D I J B]
time 10693ms: Process G started using the CPU for 152ms burst [Q C E D I J B]
time 10834ms: Process H (tau 39ms) completed I/O; added to ready queue [Q H C E D I J B]
time 10845ms: Process G completed a CPU burst; 63 bursts to go [Q H C E D I J B]
time 10845ms: Recalculated tau = 113ms for process G [Q H C E D I J B]
time 10845ms: Process G switching out of CPU; will block on I/O until time 10952ms [Q H C E D I J B]
time 10846ms: Process F (tau 83ms) completed I/O; added to ready queue [Q H F C E D I J B]
time 10849ms: Process H started using the CPU for 73ms burst [Q F C E D I J B]
time 10922ms: Process H completed a CPU burst; 68 bursts to go [Q F C E D I J B]
time 10922ms: Recalculated tau = 56ms for process H [Q F C E D I J B]
time 10922ms: Process H switching out of CPU; will block on I/O until time 10995ms [Q F C E D I J B]
time 10926ms: Process F started using the CPU for 53ms burst [Q C E D I J B]
time 10952ms: Process G (tau 113ms) completed I/O; added to ready queue [Q G C E D I J B]
time 10979ms: Process F completed a CPU burst; 13 bursts to go [Q G C E D I J B]
time 10979ms: Recalculated tau = 68ms for process F [Q G C E D I J B]
time 10979ms: Process F switching out of CPU; will block on I/O until time 11022ms [Q G C E D I J B]
time 10983ms: Process G started using the CPU for 74ms burst [Q C E D I J B]
time 10995ms: Process H (tau 56ms) completed I/O; added to ready queue [Q H C E D I J B]
time 11022ms: Process F (tau 68ms) completed I/O; added to ready queue [Q H F C E D I J B]
time 11057ms: Process G completed a CPU burst; 62 bursts to go [Q H F C E D I J B]
time 11057ms: Recalculated tau = 94ms for process G [Q H F C E D I J B]
time 11057ms: Process G switching out of CPU; will block on I/O until time 11134ms [Q H F C E D I J B]
time 11061ms: Process H started using the CPU for 3ms burst [Q F C E D I J B]
time 11064ms: Process H completed a CPU burst; 67 bursts to go [Q F C E D I J B]
time 11064ms: Recalculated tau = 30ms for process H [Q F C E D I J B]
time 11064ms: Process H switching out of CPU; will block on I/O until time 11177ms [Q F C E D I J B]
time 11068ms: Process F started using the CPU for 12ms burst [Q C E D I J B]
time 11080ms: Process F completed a CPU burst; 12 bursts to go [Q C E D I J B]
time 11080ms: Recalculated tau = 40ms for process F [Q C E D I J B]
time 11080ms: Process F switching out of CPU; will block on I/O until time 11102ms [Q C E D I J B]
time 11084ms: Process C started using the CPU for 23ms burst [Q E D I J B]
time 11102ms: Process F (tau 40ms) completed I/O; added to ready queue [Q F E D I J B]
time 11107ms: Process C completed a CPU burst; 56 bursts to go [Q F E D I J B]
time 11107ms: Recalculated tau = 77ms for process C [Q F E D I J B]
time 11107ms: Process C switching out of CPU; will block on I/O until time 11118ms [Q F E D I J B]
time 11111ms: Process F started using the CPU for 96ms burst [Q E D I J B]
time 11118ms: Process C (tau 77ms) completed I/O; added to ready queue [Q C E D I J B]
time 11134ms: Process G (tau 94ms) completed I/O; added to ready queue [Q C G E D I J B]
time 11177ms: Process H (tau 30ms) completed I/O; added to ready queue [Q H C G E D I J B]
time 11207ms: Process F completed a CPU burst; 11 bursts to go [Q H C G E D I J B]
time 11207ms: Recalculated tau = 68ms for process F [Q H C G E D I J B]
time 11207ms: Process F switching out of CPU; will block on I/O until time 11276ms [Q H C G E D I J B]
time 11211ms: Process H started using the CPU for 106ms burst [Q C G E D I J B]
time 11276ms: Process F (tau 68ms) completed I/O; added to ready queue [Q F C G E D I J B]
time 11317ms: Process H completed a CPU burst; 66 bursts to go [Q F C G E D I J B]
time 11317ms: Recalculated tau = 68ms for process H [Q F C G E D I J B]
time 11317ms: Process H switching out of CPU; will block on I/O until time 11400ms [Q F C G E D I J B]
time 11321ms: Process F started using the CPU for 48ms burst [Q C G E D I J B]
time 11369ms: Process F completed a CPU burst; 10 bursts to go [Q C G E D I J B]
time 11369ms: Recalculated tau = 58ms for process F [Q C G E D I J B]
time 11369ms: Process F switching out of CPU; will block on I/O until time 11393ms [Q C G E D I J B]
time 11373ms: Process C started using the CPU for 68ms burst [Q G E D I J B]
time 11393ms: Process F (tau 58ms) completed I/O; added to ready queue [Q F G E D I J B]
time 11400ms: Process H (tau 68ms) completed I/O; added to ready queue [Q F H G E D I J B]
time 11441ms: Process C completed a CPU burst; 55 bursts to go [Q F H G E D I J B]
time 11441ms: Recalculated tau = 73ms for process C [Q F H G E D I J B]
time 11441ms: Process C switching out of CPU; will block on I/O until time 11501ms [Q F H G E D I J B]
time 11445ms: Process F started using the CPU for 72ms burst [Q H G E D I J B]
time 11501ms: Process C (tau 73ms) completed I/O; added to ready queue [Q H C G E D I J B]
time 11517ms: Process F completed a CPU burst; 9 bursts to go [Q H C G E D I J B]
time 11517ms: Recalculated tau = 65ms for process F [Q H C G E D I J B]
time 11517ms: Process F switching out of CPU; will block on I/O until time 11561ms [Q H C G E D I J B]
time 11521ms: Process H started using the CPU for 98ms burst [Q C G E D I J B]
time 11561ms: Process F (tau 65ms) completed I/O; added to ready queue [Q F C G E D I J B]
time 11619ms: Process H completed a CPU burst; 65 bursts to go [Q F C G E D I J B]
time 11619ms: Recalculated tau = 83ms for process H [Q F C G E D I J B]
time 11619ms: Process H switching out of CPU; will block on I/O until time 11676ms [Q F C G E D I J B]
time 11623ms: Process F started using the CPU for 12ms burst [Q C G E D I J B]
time 11635ms: Process F completed a CPU burst; 8 bursts to go [Q C G E D I J B]
time 11635ms: Recalculated tau = 39ms for process F [Q C G E D I J B]
time 11635ms: Process F switching out of CPU; will block on I/O until time 11650ms [Q C G E D I J B]
time 11639ms: Process C started using the CPU for 41ms burst [Q G E D I J B]
time 11650ms: Process F (tau 39ms) completed I/O; added to ready queue [Q F G E D I J B]
time 11676ms: Process H (tau 83ms) completed I/O; added to ready queue [Q F H G E D I J B]
time 11680ms: Process C completed a CPU burst; 54 bursts to go [Q F H G E D I J B]
time 11680ms: Recalculated tau = 57ms for process C [Q F H G E D I J B]
time 11680ms: Process C switching out of CPU; will block on I/O until time 11702ms [Q F H G E D I J B]
time 11684ms: Process F started using the CPU for 41ms burst [Q H G E D I J B]
time 11702ms: Process C (tau 57ms) completed I/O; added to ready queue [Q C H G E D I J B]
time 11725ms: Process F completed a CPU burst; 7 bursts to go [Q C H G E D I J B]
time 11725ms: Recalculated tau = 40ms for process F [Q C H G E D I J B]
time 11725ms: Process F switching out of CPU; will block on I/O until time 11748ms [Q C H G E D I J B]
time 11729ms: Process C started using the CPU for 44ms burst [Q H G E D I J B]
time 11748ms: Process F (tau 40ms) completed I/O; added to ready queue [Q F H G E D I J B]
time 11773ms: Process C completed a CPU burst; 53 bursts to go [Q F H G E D I J B]
time 11773ms: Recalculated tau = 51ms for process C [Q F H G E D I J B]
time 11773ms: Process C switching out of CPU; will block on I/O until time 11836ms [Q F H G E D I J B]
time 11777ms: Process F started using the CPU for 160ms burst [Q H G E D I J B]
time 11836ms: Process C (tau 51ms) completed I/O; added to ready queue [Q C H G E D I J B]
time 11937ms: Process F completed a CPU burst; 6 bursts to go [Q C H G E D I J B]
time 11937ms: Recalculated tau = 100ms for process F [Q C H G E D I J B]
time 11937ms: Process F switching out of CPU; will block on I/O until time 11999ms [Q C H G E D I J B]
time 11941ms: Process C started using the CPU for 74ms burst [Q H G E D I J B]
time 11999ms: Process F (tau 100ms) completed I/O; added to ready queue [Q H G F E D I J B]
time 12015ms: Process C completed a CPU burst; 52 bursts to go [Q H G F E D I J B]
time 12015ms: Recalculated tau = 63ms for process C [Q H G F E D I J B]
time 12015ms: Process C switching out of CPU; will block on I/O until time 12203ms [Q H G F E D I J B]
time 12019ms: Process H started using the CPU for 20ms burst [Q G F E D I J B]
time 12039ms: Process H completed a CPU burst; 64 bursts to go [Q G F E D I J B]
time 12039ms: Recalculated tau = 52ms for process H [Q G F E D I J B]
time 12039ms: Process H switching out of CPU; will block on I/O until time 12192ms [Q G F E D I J B]
time 12043ms: Process G started using the CPU for 68ms burst [Q F E D I J B]
time 12111ms: Process G completed a CPU burst; 61 bursts to go [Q F E D I J B]
time 12111ms: Recalculated tau = 81ms for process G [Q F E D I J B]
time 12111ms: Process G switching out of CPU; will block on I/O until time 12254ms [Q F E D I J B]
time 12115ms: Process F started using the CPU for 28ms burst [Q E D I J B]
time 12143ms: Process F completed a CPU burst; 5 bursts to go [Q E D I J B]
time 12143ms: Recalculated tau = 64ms for process F [Q E D I J B]
time 12143ms: Process F switching out of CPU; will block on I/O until time 12241ms [Q E D I J B]
time 12147ms: Process E started using the CPU for 22ms burst [Q D I J B]
time 12169ms: Process E completed a CPU burst; 6 bursts to go [Q D I J B]
time 12169ms: Recalculated tau = 81ms for process E [Q D I J B]
time 12169ms: Process E switching out of CPU; will block on I/O until time 12287ms [Q D I J B]
time 12173ms: Process D started using the CPU for 55ms burst [Q I J B]
time 12192ms: Process H (tau 52ms) completed I/O; added to ready queue [Q H I J B]
time 12203ms: Process C (tau 63ms) completed I/O; added to ready queue [Q H C I J B]
time 12228ms: Process D completed a CPU burst; 25 bursts to go [Q H C I J B]
time 12228ms: Recalculated tau = 99ms for process D [Q H C I J B]
time 12228ms: Process D switching out of CPU; will block on I/O until time 12355ms [Q H C I J B]
time 12232ms: Process H started using the CPU for 50ms burst [Q C I J B]
time 12241ms: Process F (tau 64ms) completed I/O; added to ready queue [Q C F I J B]
time 12254ms: Process G (tau 81ms) completed I/O; added to ready queue [Q C F G I J B]
time 12282ms: Process H completed a CPU burst; 63 bursts to go [Q C F G I J B]
time 12282ms: Recalculated tau = 51ms for process H [Q C F G I J B]
time 12282ms: Process H switching out of CPU; will block on I/O until time 12346ms [Q C F G I J B]
time 12286ms: Process C started using the CPU for 117ms burst [Q F G I J B]
time 12287ms: Process E (tau 81ms) completed I/O; added to ready queue [Q F E G I J B]
time 12346ms: Process H (tau 51ms) completed I/O; added to ready queue [Q H F E G I J B]
time 12355ms: Process D (tau 99ms) completed I/O; added to ready queue [Q H F E G D I J B]
time 12403ms: Process C completed a CPU burst; 51 bursts to go [Q H F E G D I J B]
time 12403ms: Recalculated tau = 90ms for process C [Q H F E G D I J B]
time 12403ms: Process C switching out of CPU; will block on I/O until time 12505ms [Q H F E G D I J B]
time 12407ms: Process H started using the CPU for 55ms burst [Q F E G D I J B]
time 12462ms: Process H completed a CPU burst; 62 bursts to go [Q F E G D I J B]
time 12462ms: Recalculated tau = 53ms for process H [Q F E G D I J B]
time 12462ms: Process H switching out of CPU; will block on I/O until time 12482ms [Q F E G D I J B]
time 12466ms: Process F started using the CPU for 51ms burst [Q E G D I J B]
time 12482ms: Process H (tau 53ms) completed I/O; added to ready queue [Q H E G D I J B]
time 12505ms: Process C (tau 90ms) completed I/O; added to ready queue [Q H E G C D I J B]
time 12517ms: Process F completed a CPU burst; 4 bursts to go [Q H E G C D I J B]
time 12517ms: Recalculated tau = 58ms for process F [Q H E G C D I J B]
time 12517ms: Process F switching out of CPU; will block on I/O until time 12542ms [Q H E G C D I J B]
time 12521ms: Process H started using the CPU for 47ms burst [Q E G C D I J B]
time 12542ms: Process F (tau 58ms) completed I/O; added to ready queue [Q F E G C D I J B]
time 12568ms: Process H completed a CPU burst; 61 bursts to go [Q F E G C D I J B]
time 12568ms: Recalculated tau = 50ms for process H [Q F E G C D I J B]
time 12568ms: Process H switching out of CPU; will block on I/O until time 12703ms [Q F E G C D I J B]
time 12572ms: Process F started using the CPU for 87ms burst [Q E G C D I J B]
time 12659ms: Process F completed a CPU burst; 3 bursts to go [Q E G C D I J B]
time 12659ms: Recalculated tau = 73ms for process F [Q E G C D I J B]
time 12659ms: Process F switching out of CPU; will block on I/O until time 12718ms [Q E G C D I J B]
time 12663ms: Process E started using the CPU for 80ms burst [Q G C D I J B]
time 12703ms: Process H (tau 50ms) completed I/O; added to ready queue [Q H G C D I J B]
time 12718ms: Process F (tau 73ms) completed I/O; added to ready queue [Q H F G C D I J B]
time 12743ms: Process E completed a CPU burst; 5 bursts to go [Q H F G C D I J B]
time 12743ms: Recalculated tau = 81ms for process E [Q H F G C D I J B]
time 12743ms: Process E switching out of CPU; will block on I/O until time 12872ms [Q H F G C D I J B]
time 12747ms: Process H started using the CPU for 11ms burst [Q F G C D I J B]
time 12758ms: Process H completed a CPU burst; 60 bursts to go [Q F G C D I J B]
time 12758ms: Recalculated tau = 31ms for process H [Q F G C D I J B]
time 12758ms: Process H switching out of CPU; will block on I/O until time 12936ms [Q F G C D I J B]
time 12762ms: Process F started using the CPU for 156ms burst [Q G C D I J B]
time 12872ms: Process E (tau 81ms) completed I/O; added to ready queue [Q E G C D I J B]
time 12918ms: Process F completed a CPU burst; 2 bursts to go [Q E G C D I J B]
time 12918ms: Recalculated tau = 115ms for process F [Q E G C D I J B]
time 12918ms: Process F switching out of CPU; will block on I/O until time 12976ms [Q E G C D I J B]
time 12922ms: Process E started using the CPU for 46ms burst [Q G C D I J B]
time 12936ms: Process H (tau 31ms) completed I/O; added to ready queue [Q H G C D I J B]
time 12968ms: Process E completed a CPU burst; 4 bursts to go [Q H G C D I J B]
time 12968ms: Recalculated tau = 64ms for process E [Q H G C D I J B]
time 12968ms: Process E switching out of CPU; will block on I/O until time 13125ms [Q H G C D I J B]
time 12972ms: Process H started using the CPU for 18ms burst [Q G C D I J B]
time 12976ms: Process F (tau 115ms) completed I/O; added to ready queue [Q G C D F I J B]
time 12990ms: Process H completed a CPU burst; 59 bursts to go [Q G C D F I J B]
time 12990ms: Recalculated tau = 25ms for process H [Q G C D F I J B]
time 12990ms: Process H switching out of CPU; will block on I/O until time 13143ms [Q G C D F I J B]
time 12994ms: Process G started using the CPU for 8ms burst [Q C D F I J B]
time 13002ms: Process G completed a CPU burst; 60 bursts to go [Q C D F I J B]
time 13002ms: Recalculated tau = 45ms for process G [Q C D F I J B]
time 13002ms: Process G switching out of CPU; will block on I/O until time 13067ms [Q C D F I J B]
time 13006ms: Process C started using the CPU for 14ms burst [Q D F I J B]
time 13020ms: Process C completed a CPU burst; 50 bursts to go [Q D F I J B]
time 13020ms: Recalculated tau = 52ms for process C [Q D F I J B]
time 13020ms: Process C switching out of CPU; will block on I/O until time 13024ms [Q D F I J B]
time 13024ms: Process D started using the CPU for 27ms burst [Q F I J B]
time 13024ms: Process C (tau 52ms) completed I/O; added to ready queue [Q C F I J B]
time 13051ms: Process D completed a CPU burst; 24 bursts to go [Q C F I J B]
time 13051ms: Recalculated tau = 63ms for process D [Q C F I J B]
time 13051ms: Process D switching out of CPU; will block on I/O until time 13175ms [Q C F I J B]
time 13055ms: Process C started using the CPU for 156ms burst [Q F I J B]
time 13067ms: Process G (tau 45ms) completed I/O; added to ready queue [Q G F I J B]
time 13125ms: Process E (tau 64ms) completed I/O; added to ready queue [Q G E F I J B]
time 13143ms: Process H (tau 25ms) completed I/O; added to ready queue [Q H G E F I J B]
time 13175ms: Process D (tau 63ms) completed I/O; added to ready queue [Q H G D E F I J B]
time 13211ms: Process C completed a CPU burst; 49 bursts to go [Q H G D E F I J B]
time 13211ms: Recalculated tau = 104ms for process C [Q H G D E F I J B]
time 13211ms: Process C switching out of CPU; will block on I/O until time 13313ms [Q H G D E F I J B]
time 13215ms: Process H started using the CPU for 46ms burst [Q G D E F I J B]
time 13261ms: Process H completed a CPU burst; 58 bursts to go [Q G D E F I J B]
time 13261ms: Recalculated tau = 36ms for process H [Q G D E F I J B]
time 13261ms: Process H switching out of CPU; will block on I/O until time 13369ms [Q G D E F I J B]
time 13265ms: Process G started using the CPU for 71ms burst [Q D E F I J B]
time 13313ms: Process C (tau 104ms) completed I/O; added to ready queue [Q D E C F I J B]
time 13336ms: Process G completed a CPU burst; 59 bursts to go [Q D E C F I J B]
time 13336ms: Recalculated tau = 58ms for process G [Q D E C F I J B]
time 13336ms: Process G switching out of CPU; will block on I/O until time 13431ms [Q D E C F I J B]
time 13340ms: Process D started using the CPU for 73ms burst [Q E C F I J B]
time 13369ms: Process H (tau 36ms) completed I/O; added to ready queue [Q H E C F I J B]
time 13413ms: Process D completed a CPU burst; 23 bursts to go [Q H E C F I J B]
time 13413ms: Recalculated tau = 68ms for process D [Q H E C F I J B]
time 13413ms: Process D switching out of CPU; will block on I/O until time 13470ms [Q H E C F I J B]
time 13417ms: Process H started using the CPU for 51ms burst [Q E C F I J B]
time 13431ms: Process G (tau 58ms) completed I/O; added to ready queue [Q G E C F I J B]
time 13468ms: Process H completed a CPU burst; 57 bursts to go [Q G E C F I J B]
time 13468ms: Recalculated tau = 44ms for process H [Q G E C F I J B]
time 13468ms: Process H switching out of CPU; will block on I/O until time 13568ms [Q G E C F I J B]
time 13470ms: Process D (tau 68ms) completed I/O; added to ready queue [Q G E D C F I J B]
time 13472ms: Process G started using the CPU for 64ms burst [Q E D C F I J B]
time 13536ms: Process G completed a CPU burst; 58 bursts to go [Q E D C F I J B]
time 13536ms: Recalculated tau = 61ms for process G [Q E D C F I J B]
time 13536ms: Process G switching out of CPU; will block on I/O until time 13575ms [Q E D C F I J B]
time 13540ms: Process E started using the CPU for 54ms burst [Q D C F I J B]
time 13568ms: Process H (tau 44ms) completed I/O; added to ready queue [Q H D C F I J B]
time 13575ms: Process G (tau 61ms) completed I/O; added to ready queue [Q H G D C F I J B]
time 13594ms: Process E completed a CPU burst; 3 bursts to go [Q H G D C F I J B]
time 13594ms: Recalculated tau = 59ms for process E [Q H G D C F I J B]
time 13594ms: Process E switching out of CPU; will block on I/O until time 13602ms [Q H G D C F I J B]
time 13598ms: Process H started using the CPU for 14ms burst [Q G D C F I J B]
time 13602ms: Process E (tau 59ms) completed I/O; added to ready queue [Q E G D C F I J B]
time 13612ms: Process H completed a CPU burst; 56 bursts to go [Q E G D C F I J B]
time 13612ms: Recalculated tau = 29ms for process H [Q E G D C F I J B]
time 13612ms: Process H switching out of CPU; will block on I/O until time 13625ms [Q E G D C F I J B]
time 13616ms: Process E started using the CPU for 164ms burst [Q G D C F I J B]
time 13625ms: Process H (tau 29ms) completed I/O; added to ready queue [Q H G D C F I J B]
time 13780ms: Process E completed a CPU burst; 2 bursts to go [Q H G D C F I J B]
time 13780ms: Recalculated tau = 112ms for process E [Q H G D C F I J B]
time 13780ms: Process E switching out of CPU; will block on I/O until time 13797ms [Q H G D C F I J B]
time 13784ms: Process H started using the CPU for 4ms burst [Q G D C F I J B]
time 13788ms: Process H completed a CPU burst; 55 bursts to go [Q G D C F I J B]
time 13788ms: Recalculated tau = 17ms for process H [Q G D C F I J B]
time 13788ms: Process H switching out of CPU; will block on I/O until time 13809ms [Q G D C F I J B]
time 13792ms: Process G started using the CPU for 17ms burst [Q D C F I J B]
time 13797ms: Process E (tau 112ms) completed I/O; added to ready queue [Q D C E F I J B]
time 13809ms: Process G completed a CPU burst; 57 bursts to go [Q D C E F I J B]
time 13809ms: Recalculated tau = 39ms for process G [Q D C E F I J B]
time 13809ms: Process G switching out of CPU; will block on I/O until time 13831ms [Q D C E F I J B]
time 13809ms: Process H (tau 17ms) completed I/O; added to ready queue [Q H D C E F I J B]
time 13813ms: Process H started using the CPU for 19ms burst [Q D C E F I J B]
time 13831ms: Process G (tau 39ms) completed I/O; added to ready queue [Q G D C E F I J B]
time 13832ms: Process H completed a CPU burst; 54 bursts to go [Q G D C E F I J B]
time 13832ms: Recalculated tau = 18ms for process H [Q G D C E F I J B]
time 13832ms: Process H switching out of CPU; will block on I/O until time 13893ms [Q G D C E F I J B]
time 13836ms: Process G started using the CPU for 2ms burst [Q D C E F I J B]
time 13838ms: Process G completed a CPU burst; 56 bursts to go [Q D C E F I J B]
time 13838ms: Recalculated tau = 21ms for process G [Q D C E F I J B]
time 13838ms: Process G switching out of CPU; will block on I/O until time 13988ms [Q D C E F I J B]
time 13842ms: Process D started using the CPU for 66ms burst [Q C E F I J B]
time 13893ms: Process H (tau 18ms) completed I/O; added to ready queue [Q H C E F I J B]
time 13908ms: Process D completed a CPU burst; 22 bursts to go [Q H C E F I J B]
time 13908ms: Recalculated tau = 67ms for process D [Q H C E F I J B]
time 13908ms: Process D switching out of CPU; will block on I/O until time 13934ms [Q H C E F I J B]
time 13912ms: Process H started using the CPU for 10ms burst [Q C E F I J B]
time 13922ms: Process H completed a CPU burst; 53 bursts to go [Q C E F I J B]
time 13922ms: Recalculated tau = 14ms for process H [Q C E F I J B]
time 13922ms: Process H switching out of CPU; will block on I/O until time 14016ms [Q C E F I J B]
time 13926ms: Process C started using the CPU for 18ms burst [Q E F I J B]
time 13934ms: Process D (tau 67ms) completed I/O; added to ready queue [Q D E F I J B]
time 13944ms: Process C completed a CPU burst; 48 bursts to go [Q D E F I J B]
time 13944ms: Recalculated tau = 61ms for process C [Q D E F I J B]
time 13944ms: Process C switching out of CPU; will block on I/O until time 13990ms [Q D E F I J B]
time 13948ms: Process D started using the CPU for 70ms burst [Q E F I J B]
time 13988ms: Process G (tau 21ms) completed I/O; added to ready queue [Q G E F I J B]
time 13990ms: Process C (tau 61ms) completed I/O; added to ready queue [Q G C E F I J B]
time 14016ms: Process H (tau 14ms) completed I/O; added to ready queue [Q H G C E F I J B]
time 14018ms: Process D completed a CPU burst; 21 bursts to go [Q H G C E F I J B]
time 14018ms: Recalculated tau = 69ms for process D [Q H G C E F I J B]
time 14018ms: Process D switching out of CPU; will block on I/O until time 14051ms [Q H G C E F I J B]
time 14022ms: Process H started using the CPU for 126ms burst [Q G C E F I J B]
time 14051ms: Process D (tau 69ms) completed I/O; added to ready queue [Q G C D E F I J B]
time 14148ms: Process H completed a CPU burst; 52 bursts to go [Q G C D E F I J B]
time 14148ms: Recalculated tau = 70ms for process H [Q G C D E F I J B]
time 14148ms: Process H switching out of CPU; will block on I/O until time 14179ms [Q G C D E F I J B]
time 14152ms: Process G started using the CPU for 21ms burst [Q C D E F I J B]
time 14173ms: Process G completed a CPU burst; 55 bursts to go [Q C D E F I J B]
time 14173ms: Recalculated tau = 21ms for process G [Q C D E F I J B]
time 14173ms: Process G switching out of CPU; will block on I/O until time 14316ms [Q C D E F I J B]
time 14177ms: Process C started using the CPU for 9ms burst [Q D E F I J B]
time 14179ms: Process H (tau 70ms) completed I/O; added to ready queue [Q D H E F I J B]
time 14186ms: Process C completed a CPU burst; 47 bursts to go [Q D H E F I J B]
time 14186ms: Recalculated tau = 35ms for process C [Q D H E F I J B]
time 14186ms: Process C switching out of CPU; will block on I/O until time 14296ms [Q D H E F I J B]
time 14190ms: Process D started using the CPU for 40ms burst [Q H E F I J B]
time 14230ms: Process D completed a CPU burst; 20 bursts to go [Q H E F I J B]
time 14230ms: Recalculated tau = 55ms for process D [Q H E F I J B]
time 14230ms: Process D switching out of CPU; will block on I/O until time 14238ms [Q H E F I J B]
time 14234ms: Process H started using the CPU for 3ms burst [Q E F I J B]
time 14237ms: Process H completed a CPU burst; 51 bursts to go [Q E F I J B]
time 14237ms: Recalculated tau = 37ms for process H [Q E F I J B]
time 14237ms: Process H switching out of CPU; will block on I/O until time 14333ms [Q E F I J B]
time 14238ms: Process D (tau 55ms) completed I/O; added to ready queue [Q D E F I J B]
time 14241ms: Process D started using the CPU for 65ms burst [Q E F I J B]
time 14296ms: Process C (tau 35ms) completed I/O; added to ready queue [Q C E F I J B]
time 14306ms: Process D completed a CPU burst; 19 bursts to go [Q C E F I J B]
time 14306ms: Recalculated tau = 60ms for process D [Q C E F I J B]
time 14306ms: Process D switching out of CPU; will block on I/O until time 14352ms [Q C E F I J B]
time 14310ms: Process C started using the CPU for 1ms burst [Q E F I J B]
time 14311ms: Process C completed a CPU burst; 46 bursts to go [Q E F I J B]
time 14311ms: Recalculated tau = 18ms for process C [Q E F I J B]
time 14311ms: Process C switching out of CPU; will block on I/O until time 14379ms [Q E F I J B]
time 14315ms: Process E started using the CPU for 131ms burst [Q F I J B]
time 14316ms: Process G (tau 21ms) completed I/O; added to ready queue [Q G F I J B]
time 14333ms: Process H (tau 37ms) completed I/O; added to ready queue [Q G H F I J B]
time 14352ms: Process D (tau 60ms) completed I/O; added to ready queue [Q G H D F I J B]
time 14379ms: Process C (tau 18ms) completed I/O; added to ready queue [Q C G H D F I J B]
time 14446ms: Process E completed a CPU burst; 1 burst to go [Q C G H D F I J B]
time 14446ms: Recalculated tau = 122ms for process E [Q C G H D F I J B]
time 14446ms: Process E switching out of CPU; will block on I/O until time 14456ms [Q C G H D F I J B]
time 14450ms: Process C started using the CPU for 168ms burst [Q G H D F I J B]
time 14456ms: Process E (tau 122ms) completed I/O; added to ready queue [Q G H D F E I J B]
time 14618ms: Process C completed a CPU burst; 45 bursts to go [Q G H D F E I J B]
time 14618ms: Recalculated tau = 93ms for process C [Q G H D F E I J B]
time 14618ms: Process C switching out of CPU; will block on I/O until time 14738ms [Q G H D F E I J B]
time 14622ms: Process G started using the CPU for 22ms burst [Q H D F E I J B]
time 14644ms: Process G completed a CPU burst; 54 bursts to go [Q H D F E I J B]
time 14644ms: Recalculated tau = 22ms for process G [Q H D F E I J B]
time 14644ms: Process G switching out of CPU; will block on I/O until time 14732ms [Q H D F E I J B]
time 14648ms: Process H started using the CPU for 12ms burst [Q D F E I J B]
time 14660ms: Process H completed a CPU burst; 50 bursts to go [Q D F E I J B]
time 14660ms: Recalculated tau = 25ms for process H [Q D F E I J B]
time 14660ms: Process H switching out of CPU; will block on I/O until time 14673ms [Q D F E I J B]
time 14664ms: Process D started using the CPU for 13ms burst [Q F E I J B]
time 14673ms: Process H (tau 25ms) completed I/O; added to ready queue [Q H F E I J B]
time 14677ms: Process D completed a CPU burst; 18 bursts to go [Q H F E I J B]
time 14677ms: Recalculated tau = 37ms for process D [Q H F E I J B]
time 14677ms: Process D switching out of CPU; will block on I/O until time 14717ms [Q H F E I J B]
time 14681ms: Process H started using the CPU for 188ms burst [Q F E I J B]
time 14717ms: Process D (tau 37ms) completed I/O; added to ready queue [Q D F E I J B]
time 14732ms: Process G (tau 22ms) completed I/O; added to ready queue [Q G D F E I J B]
time 14738ms: Process C (tau 93ms) completed I/O; added to ready queue [Q G D C F E I J B]
time 14869ms: Process H completed a CPU burst; 49 bursts to go [Q G D C F E I J B]
time 14869ms: Recalculated tau = 107ms for process H [Q G D C F E I J B]
time 14869ms: Process H switching out of CPU; will block on I/O until time 15016ms [Q G D C F E I J B]
time 14873ms: Process G started using the CPU for 72ms burst [Q D C F E I J B]
time 14945ms: Process G completed a CPU burst; 53 bursts to go [Q D C F E I J B]
time 14945ms: Recalculated tau = 47ms for process G [Q D C F E I J B]
time 14945ms: Process G switching out of CPU; will block on I/O until time 15139ms [Q D C F E I J B]
time 14949ms: Process D started using the CPU for 128ms burst [Q C F E I J B]
time 15016ms: Process H (tau 107ms) completed I/O; added to ready queue [Q C H F E I J B]
time 15077ms: Process D completed a CPU burst; 17 bursts to go [Q C H F E I J B]
time 15077ms: Recalculated tau = 83ms for process D [Q C H F E I J B]
time 15077ms: Process D switching out of CPU; will block on I/O until time 15094ms [Q C H F E I J B]
time 15081ms: Process C started using the CPU for 10ms burst [Q H F E I J B]
time 15091ms: Process C completed a CPU burst; 44 bursts to go [Q H F E I J B]
time 15091ms: Recalculated tau = 52ms for process C [Q H F E I J B]
time 15091ms: Process C switching out of CPU; will block on I/O until time 15140ms [Q H F E I J B]
time 15094ms: Process D (tau 83ms) completed I/O; added to ready queue [Q D F E I J B]
time 15095ms: Process H started using the CPU for 114ms burst [Q D F E I J B]
time 15139ms: Process G (tau 47ms) completed I/O; added to ready queue [Q G D F E I J B]
time 15140ms: Process C (tau 52ms) completed I/O; added to ready queue [Q G C D F E I J B]
time 15209ms: Process H completed a CPU burst; 48 bursts to go [Q G C D F E I J B]
time 15209ms: Recalculated tau = 111ms for process H [Q G C D F E I J B]
time 15209ms: Process H switching out of CPU; will block on I/O until time 15245ms [Q G C D F E I J B]
time 15213ms: Process G started using the CPU for 13ms burst [Q C D F E I J B]
time 15226ms: Process G completed a CPU burst; 52 bursts to go [Q C D F E I J B]
time 15226ms: Recalculated tau = 30ms for process G [Q C D F E I J B]
time 15226ms: Process G switching out of CPU; will block on I/O until time 15337ms [Q C D F E I J B]
time 15230ms: Process C started using the CPU for 68ms burst [Q D F E I J B]
time 15245ms: Process H (tau 111ms) completed I/O; added to ready queue [Q D H F E I J B]
time 15298ms: Process C completed a CPU burst; 43 bursts to go [Q D H F E I J B]
time 15298ms: Recalculated tau = 60ms for process C [Q D H F E I J B]
time 15298ms: Process C switching out of CPU; will block on I/O until time 15355ms [Q D H F E I J B]
time 15302ms: Process D started using the CPU for 94ms burst [Q H F E I J B]
time 15337ms: Process G (tau 30ms) completed I/O; added to ready queue [Q G H F E I J B]
time 15355ms: Process C (tau 60ms) completed I/O; added to ready queue [Q G C H F E I J B]
time 15396ms: Process D completed a CPU burst; 16 bursts to go [Q G C H F E I J B]
time 15396ms: Recalculated tau = 89ms for process D [Q G C H F E I J B]
time 15396ms: Process D switching out of CPU; will block on I/O until time 15510ms [Q G C H F E I J B]
time 15400ms: Process G started using the CPU for 44ms burst [Q C H F E I J B]
time 15444ms: Process G completed a CPU burst; 51 bursts to go [Q C H F E I J B]
time 15444ms: Recalculated tau = 37ms for process G [Q C H F E I J B]
time 15444ms: Process G switching out of CPU; will block on I/O until time 15541ms [Q C H F E I J B]
time 15448ms: Process C started using the CPU for 30ms burst [Q H F E I J B]
time 15478ms: Process C completed a CPU burst; 42 bursts to go [Q H F E I J B]
time 15478ms: Recalculated tau = 45ms for process C [Q H F E I J B]
time 15478ms: Process C switching out of CPU; will block on I/O until time 15577ms [Q H F E I J B]
time 15482ms: Process H started using the CPU for 99ms burst [Q F E I J B]
time 15510ms: Process D (tau 89ms) completed I/O; added to ready queue [Q D F E I J B]
time 15541ms: Process G (tau 37ms) completed I/O; added to ready queue [Q G D F E I J B]
time 15577ms: Process C (tau 45ms) completed I/O; added to ready queue [Q G C D F E I J B]
time 15581ms: Process H completed a CPU burst; 47 bursts to go [Q G C D F E I J B]
time 15581ms: Recalculated tau = 105ms for process H [Q G C D F E I J B]
time 15581ms: Process H switching out of CPU; will block on I/O until time 15584ms [Q G C D F E I J B]
time 15584ms: Process H (tau 105ms) completed I/O; added to ready queue [Q C D H F E I J B]
time 15585ms: Process G started using the CPU for 28ms burst [Q C D H F E I J B]
time 15613ms: Process G completed a CPU burst; 50 bursts to go [Q C D H F E I J B]
time 15613ms: Recalculated tau = 33ms for process G [Q C D H F E I J B]
time 15613ms: Process G switching out of CPU; will block on I/O until time 15645ms [Q C D H F E I J B]
time 15617ms: Process C started using the CPU for 54ms burst [Q D H F E I J B]
time 15645ms: Process G (tau 33ms) completed I/O; added to ready queue [Q G D H F E I J B]
time 15671ms: Process C completed a CPU burst; 41 bursts to go [Q G D H F E I J B]
time 15671ms: Recalculated tau = 50ms for process C [Q G D H F E I J B]
time 15671ms: Process C switching out of CPU; will block on I/O until time 15719ms [Q G D H F E I J B]
time 15675ms: Process G started using the CPU for 19ms burst [Q D H F E I J B]
time 15694ms: Process G completed a CPU burst; 49 bursts to go [Q D H F E I J B]
time 15694ms: Recalculated tau = 26ms for process G [Q D H F E I J B]
time 15694ms: Process G switching out of CPU; will block on I/O until time 15717ms [Q D H F E I J B]
time 15698ms: Process D started using the CPU for 43ms burst [Q H F E I J B]
time 15717ms: Process G (tau 26ms) completed I/O; added to ready queue [Q G H F E I J B]
time 15719ms: Process C (tau 50ms) completed I/O; added to ready queue [Q G C H F E I J B]
time 15741ms: Process D completed a CPU burst; 15 bursts to go [Q G C H F E I J B]
time 15741ms: Recalculated tau = 66ms for process D [Q G C H F E I J B]
time 15741ms: Process D switching out of CPU; will block on I/O until time 15773ms [Q G C H F E I J B]
time 15745ms: Process G started using the CPU for 2ms burst [Q C H F E I J B]
time 15747ms: Process G completed a CPU burst; 48 bursts to go [Q C H F E I J B]
time 15747ms: Recalculated tau = 14ms for process G [Q C H F E I J B]
time 15747ms: Process G switching out of CPU; will block on I/O until time 15820ms [Q C H F E I J B]
time 15751ms: Process C started using the CPU for 132ms burst [Q H F E I J B]
time 15773ms: Process D (tau 66ms) completed I/O; added to ready queue [Q D H F E I J B]
time 15820ms: Process G (tau 14ms) completed I/O; added to ready queue [Q G D H F E I J B]
time 15883ms: Process C completed a CPU burst; 40 bursts to go [Q G D H F E I J B]
time 15883ms: Recalculated tau = 91ms for process C [Q G D H F E I J B]
time 15883ms: Process C switching out of CPU; will block on I/O until time 16048ms [Q G D H F E I J B]
time 15887ms: Process G started using the CPU for 26ms burst [Q D H F E I J B]
time 15913ms: Process G completed a CPU burst; 47 bursts to go [Q D H F E I J B]
time 15913ms: Recalculated tau = 20ms for process G [Q D H F E I J B]
time 15913ms: Process G switching out of CPU; will block on I/O until time 15942ms [Q D H F E I J B]
time 15917ms: Process D started using the CPU for 47ms burst [Q H F E I J B]
time 15942ms: Process G (tau 20ms) completed I/O; added to ready queue [Q G H F E I J B]
time 15964ms: Process D completed a CPU burst; 14 bursts to go [Q G H F E I J B]
time 15964ms: Recalculated tau = 57ms for process D [Q G H F E I J B]
time 15964ms: Process D switching out of CPU; will block on I/O until time 16016ms [Q G H F E I J B]
time 15968ms: Process G started using the CPU for 49ms burst [Q H F E I J B]
time 16016ms: Process D (tau 57ms) completed I/O; added to ready queue [Q D H F E I J B]
time 16017ms: Process G completed a CPU burst; 46 bursts to go [Q D H F E I J B]
time 16017ms: Recalculated tau = 35ms for process G [Q D H F E I J B]
time 16017ms: Process G switching out of CPU; will block on I/O until time 16036ms [Q D H F E I J B]
time 16021ms: Process D started using the CPU for 5ms burst [Q H F E I J B]
time 16026ms: Process D completed a CPU burst; 13 bursts to go [Q H F E I J B]
time 16026ms: Recalculated tau = 31ms for process D [Q H F E I J B]
time 16026ms: Process D switching out of CPU; will block on I/O until time 16226ms [Q H F E I J B]
time 16030ms: Process H started using the CPU for 31ms burst [Q F E I J B]
time 16036ms: Process G (tau 35ms) completed I/O; added to ready queue [Q G F E I J B]
time 16048ms: Process C (tau 91ms) completed I/O; added to ready queue [Q G C F E I J B]
time 16061ms: Process H completed a CPU burst; 46 bursts to go [Q G C F E I J B]
time 16061ms: Recalculated tau = 68ms for process H [Q G C F E I J B]
time 16061ms: Process H switching out of CPU; will block on I/O until time 16226ms [Q G C F E I J B]
time 16065ms: Process G started using the CPU for 185ms burst [Q C F E I J B]
time 16226ms: Process D (tau 31ms) completed I/O; added to ready queue [Q D C F E I J B]
time 16226ms: Process H (tau 68ms) completed I/O; added to ready queue [Q D H C F E I J B]
time 16250ms: Process G completed a CPU burst; 45 bursts to go [Q D H C F E I J B]
time 16250ms: Recalculated tau = 110ms for process G [Q D H C F E I J B]
time 16250ms: Process G switching out of CPU; will block on I/O until time 16286ms [Q D H C F E I J B]
time 16254ms: Process D started using the CPU for 122ms burst [Q H C F E I J B]
time 16286ms: Process G (tau 110ms) completed I/O; added to ready queue [Q H C G F E I J B]
time 16376ms: Process D completed a CPU burst; 12 bursts to go [Q H C G F E I J B]
time 16376ms: Recalculated tau = 77ms for process D [Q H C G F E I J B]
time 16376ms: Process D switching out of CPU; will block on I/O until time 16413ms [Q H C G F E I J B]
time 16380ms: Process H started using the CPU for 2ms burst [Q C G F E I J B]
time 16382ms: Process H completed a CPU burst; 45 bursts to go [Q C G F E I J B]
time 16382ms: Recalculated tau = 35ms for process H [Q C G F E I J B]
time 16382ms: Process H switching out of CPU; will block on I/O until time 16580ms [Q C G F E I J B]
time 16386ms: Process C started using the CPU for 37ms burst [Q G F E I J B]
time 16413ms: Process D (tau 77ms) completed I/O; added to ready queue [Q D G F E I J B]
time 16423ms: Process C completed a CPU burst; 39 bursts to go [Q D G F E I J B]
time 16423ms: Recalculated tau = 64ms for process C [Q D G F E I J B]
time 16423ms: Process C switching out of CPU; will block on I/O until time 16531ms [Q D G F E I J B]
time 16427ms: Process D started using the CPU for 31ms burst [Q G F E I J B]
time 16458ms: Process D completed a CPU burst; 11 bursts to go [Q G F E I J B]
time 16458ms: Recalculated tau = 54ms for process D [Q G F E I J B]
time 16458ms: Process D switching out of CPU; will block on I/O until time 16467ms [Q G F E I J B]
time 16462ms: Process G started using the CPU for 81ms burst [Q F E I J B]
time 16467ms: Process D (tau 54ms) completed I/O; added to ready queue [Q D F E I J B]
time 16531ms: Process C (tau 64ms) completed I/O; added to ready queue [Q D C F E I J B]
time 16543ms: Process G completed a CPU burst; 44 bursts to go [Q D C F E I J B]
time 16543ms: Recalculated tau = 96ms for process G [Q D C F E I J B]
time 16543ms: Process G switching out of CPU; will block on I/O until time 16590ms [Q D C F E I J B]
time 16547ms: Process D started using the CPU for 61ms burst [Q C F E I J B]
time 16580ms: Process H (tau 35ms) completed I/O; added to ready queue [Q H C F E I J B]
time 16590ms: Process G (tau 96ms) completed I/O; added to ready queue [Q H C G F E I J B]
time 16608ms: Process D completed a CPU burst; 10 bursts to go [Q H C G F E I J B]
time 16608ms: Recalculated tau = 58ms for process D [Q H C G F E I J B]
time 16608ms: Process D switching out of CPU; will block on I/O until time 16684ms [Q H C G F E I J B]
time 16612ms: Process H started using the CPU for 108ms burst [Q C G F E I J B]
time 16684ms: Process D (tau 58ms) completed I/O; added to ready queue [Q D C G F E I J B]
time 16720ms: Process H completed a CPU burst; 44 bursts to go [Q D C G F E I J B]
time 16720ms: Recalculated tau = 72ms for process H [Q D C G F E I J B]
time 16720ms: Process H switching out of CPU; will block on I/O until time 16797ms [Q D C G F E I J B]
time 16724ms: Process D started using the CPU for 7ms burst [Q C G F E I J B]
time 16731ms: Process D completed a CPU burst; 9 bursts to go [Q C G F E I J B]
time 16731ms: Recalculated tau = 33ms for process D [Q C G F E I J B]
time 16731ms: Process D switching out of CPU; will block on I/O until time 16897ms [Q C G F E I J B]
time 16735ms: Process C started using the CPU for 2ms burst [Q G F E I J B]
time 16737ms: Process C completed a CPU burst; 38 bursts to go [Q G F E I J B]
time 16737ms: Recalculated tau = 33ms for process C [Q G F E I J B]
time 16737ms: Process C switching out of CPU; will block on I/O until time 16825ms [Q G F E I J B]
time 16741ms: Process G started using the CPU for 57ms burst [Q F E I J B]
time 16797ms: Process H (tau 72ms) completed I/O; added to ready queue [Q H F E I J B]
time 16798ms: Process G completed a CPU burst; 43 bursts to go [Q H F E I J B]
time 16798ms: Recalculated tau = 77ms for process G [Q H F E I J B]
time 16798ms: Process G switching out of CPU; will block on I/O until time 16867ms [Q H F E I J B]
time 16802ms: Process H started using the CPU for 66ms burst [Q F E I J B]
time 16825ms: Process C (tau 33ms) completed I/O; added to ready queue [Q C F E I J B]
time 16867ms: Process G (tau 77ms) completed I/O; added to ready queue [Q C G F E I J B]
time 16868ms: Process H completed a CPU burst; 43 bursts to go [Q C G F E I J B]
time 16868ms: Recalculated tau = 69ms for process H [Q C G F E I J B]
time 16868ms: Process H switching out of CPU; will block on I/O until time 16910ms [Q C G F E I J B]
time 16872ms: Process C started using the CPU for 102ms burst [Q G F E I J B]
time 16897ms: Process D (tau 33ms) completed I/O; added to ready queue [Q D G F E I J B]
time 16910ms: Process H (tau 69ms) completed I/O; added to ready queue [Q D H G F E I J B]
time 16974ms: Process C completed a CPU burst; 37 bursts to go [Q D H G F E I J B]
time 16974ms: Recalculated tau = 68ms for process C [Q D H G F E I J B]
time 16974ms: Process C switching out of CPU; will block on I/O until time 17099ms [Q D H G F E I J B]
time 16978ms: Process D started using the CPU for 2ms burst [Q H G F E I J B]
time 16980ms: Process D completed a CPU burst; 8 bursts to go [Q H G F E I J B]
time 16980ms: Recalculated tau = 18ms for process D [Q H G F E I J B]
time 16980ms: Process D switching out of CPU; will block on I/O until time 16993ms [Q H G F E I J B]
time 16984ms: Process H started using the CPU for 115ms burst [Q G F E I J B]
time 16993ms: Process D (tau 18ms) completed I/O; added to ready queue [Q D G F E I J B]
time 17099ms: Process H completed a CPU burst; 42 bursts to go [Q D G F E I J B]
