Process A [NEW] (arrival time 9 ms) 16 CPU bursts
Process B [NEW] (arrival time 18 ms) 21 CPU bursts
Process C [NEW] (arrival time 84 ms) 82 CPU bursts
Process D [NEW] (arrival time 86 ms) 36 CPU bursts
Process E [NEW] (arrival time 2 ms) 26 CPU bursts
Process F [NEW] (arrival time 25 ms) 39 CPU bursts
Process G [NEW] (arrival time 13 ms) 76 CPU bursts
Process H [NEW] (arrival time 46 ms) 82 CPU bursts
Process I [NEW] (arrival time 64 ms) 63 CPU bursts
Process J [NEW] (arrival time 31 ms) 21 CPU bursts
Process K [NEW] (arrival time 56 ms) 1 CPU burst
Process L [NEW] (arrival time 12 ms) 3 CPU bursts
time 0ms: Simulator started for SJF [Q <empty>]
time 2ms: Process E (tau 100ms) arrived; added to ready queue [Q E]
time 4ms: Process E started using the CPU for 11ms burst [Q <empty>]
time 9ms: Process A (tau 100ms) arrived; added to ready queue [Q A]
time 12ms: Process L (tau 100ms) arrived; added to ready queue [Q A L]
time 13ms: Process G (tau 100ms) arrived; added to ready queue [Q A G L]
time 15ms: Process E completed a CPU burst; 25 bursts to go [Q A G L]
time 15ms: Recalculated tau = 56ms for process E [Q A G L]
time 15ms: Process E switching out of CPU; will block on I/O until time 34ms [Q A G L]
time 18ms: Process B (tau 100ms) arrived; added to ready queue [Q B G L]
time 19ms: Process A started using the CPU for 56ms burst [Q B G L]
time 25ms: Process F (tau 100ms) arrived; added to ready queue [Q B F G L]
time 31ms: Process J (tau 100ms) arrived; added to ready queue [Q B F G J L]
time 34ms: Process E (tau 56ms) completed I/O; added to ready queue [Q E B F G J L]
time 46ms: Process H (tau 100ms) arrived; added to ready queue [Q E B F G H J L]
time 56ms: Process K (tau 100ms) arrived; added to ready queue [Q E B F G H J K L]
time 64ms: Process I (tau 100ms) arrived; added to ready queue [Q E B F G H I J K L]
time 75ms: Process A completed a CPU burst; 15 bursts to go [Q E B F G H I J K L]
time 75ms: Recalculated tau = 78ms for process A [Q E B F G H I J K L]
time 75ms: Process A switching out of CPU; will block on I/O until time 100ms [Q E B F G H I J K L]
time 79ms: Process E started using the CPU for 65ms burst [Q B F G H I J K L]
time 84ms: Process C (tau 100ms) arrived; added to ready queue [Q B C F G H I J K L]
time 86ms: Process D (tau 100ms) arrived; added to ready queue [Q B C D F G H I J K L]
time 100ms: Process A (tau 78ms) completed I/O; added to ready queue [Q A B C D F G H I J K L]
time 144ms: Process E completed a CPU burst; 24 bursts to go [Q A B C D F G H I J K L]
time 144ms: Recalculated tau = 61ms for process E [Q A B C D F G H I J K L]
time 144ms: Process E switching out of CPU; will block on I/O until time 201ms [Q A B C D F G H I J K L]
time 148ms: Process A started using the CPU for 60ms burst [Q B C D F G H I J K L]
time 201ms: Process E (tau 61ms) completed I/O; added to ready queue [Q E B C D F G H I J K L]
time 208ms: Process A completed a CPU burst; 14 bursts to go [Q E B C D F G H I J K L]
time 208ms: Recalculated tau = 69ms for process A [Q E B C D F G H I J K L]
time 208ms: Process A switching out of CPU; will block on I/O until time 363ms [Q E B C D F G H I J K L]
time 212ms: Process E started using the CPU for 52ms burst [Q B C D F G H I J K L]
time 264ms: Process E completed a CPU burst; 23 bursts to go [Q B C D F G H I J K L]
time 264ms: Recalculated tau = 57ms for process E [Q B C D F G H I J K L]
time 264ms: Process E switching out of CPU; will block on I/O until time 362ms [Q B C D F G H I J K L]
time 268ms: Process B started using the CPU for 106ms burst [Q C D F G H I J K L]
time 362ms: Process E (tau 57ms) completed I/O; added to ready queue [Q E C D F G H I J K L]
time 363ms: Process A (tau 69ms) completed I/O; added to ready queue [Q E A C D F G H I J K L]
time 374ms: Process B completed a CPU burst; 20 bursts to go [Q E A C D F G H I J K L]
time 374ms: Recalculated tau = 103ms for process B [Q E A C D F G H I J K L]
time 374ms: Process B switching out of CPU; will block on I/O until time 532ms [Q E A C D F G H I J K L]
time 378ms: Process E started using the CPU for 199ms burst [Q A C D F G H I J K L]
time 532ms: Process B (tau 103ms) completed I/O; added to ready queue [Q A C D F G H I J K L B]
time 577ms: Process E completed a CPU burst; 22 bursts to go [Q A C D F G H I J K L B]
time 577ms: Recalculated tau = 128ms for process E [Q A C D F G H I J K L B]
time 577ms: Process E switching out of CPU; will block on I/O until time 589ms [Q A C D F G H I J K L B]
time 581ms: Process A started using the CPU for 39ms burst [Q C D F G H I J K L B]
time 589ms: Process E (tau 128ms) completed I/O; added to ready queue [Q C D F G H I J K L B E]
time 620ms: Process A completed a CPU burst; 13 bursts to go [Q C D F G H I J K L B E]
time 620ms: Recalculated tau = 54ms for process A [Q C D F G H I J K L B E]
time 620ms: Process A switching out of CPU; will block on I/O until time 672ms [Q C D F G H I J K L B E]
time 624ms: Process C started using the CPU for 79ms burst [Q D F G H I J K L B E]
time 672ms: Process A (tau 54ms) completed I/O; added to ready queue [Q A D F G H I J K L B E]
time 703ms: Process C completed a CPU burst; 81 bursts to go [Q A D F G H I J K L B E]
time 703ms: Recalculated tau = 90ms for process C [Q A D F G H I J K L B E]
time 703ms: Process C switching out of CPU; will block on I/O until time 862ms [Q A D F G H I J K L B E]
time 707ms: Process A started using the CPU for 47ms burst [Q D F G H I J K L B E]
time 754ms: Process A completed a CPU burst; 12 bursts to go [Q D F G H I J K L B E]
time 754ms: Recalculated tau = 51ms for process A [Q D F G H I J K L B E]
time 754ms: Process A switching out of CPU; will block on I/O until time 758ms [Q D F G H I J K L B E]
time 758ms: Process D started using the CPU for 22ms burst [Q F G H I J K L B E]
time 758ms: Process A (tau 51ms) completed I/O; added to ready queue [Q A F G H I J K L B E]
time 780ms: Process D completed a CPU burst; 35 bursts to go [Q A F G H I J K L B E]
time 780ms: Recalculated tau = 61ms for process D [Q A F G H I J K L B E]
time 780ms: Process D switching out of CPU; will block on I/O until time 797ms [Q A F G H I J K L B E]
time 784ms: Process A started using the CPU for 137ms burst [Q F G H I J K L B E]
time 797ms: Process D (tau 61ms) completed I/O; added to ready queue [Q D F G H I J K L B E]
time 862ms: Process C (tau 90ms) completed I/O; added to ready queue [Q D C F G H I J K L B E]
time 921ms: Process A completed a CPU burst; 11 bursts to go [Q D C F G H I J K L B E]
time 921ms: Recalculated tau = 94ms for process A [Q D C F G H I J K L B E]
time 921ms: Process A switching out of CPU; will block on I/O until time 947ms [Q D C F G H I J K L B E]
time 925ms: Process D started using the CPU for 52ms burst [Q C F G H I J K L B E]
time 947ms: Process A (tau 94ms) completed I/O; added to ready queue [Q C A F G H I J K L B E]
time 977ms: Process D completed a CPU burst; 34 bursts to go [Q C A F G H I J K L B E]
time 977ms: Recalculated tau = 57ms for process D [Q C A F G H I J K L B E]
time 977ms: Process D switching out of CPU; will block on I/O until time 988ms [Q C A F G H I J K L B E]
time 981ms: Process C started using the CPU for 148ms burst [Q A F G H I J K L B E]
time 988ms: Process D (tau 57ms) completed I/O; added to ready queue [Q D A F G H I J K L B E]
time 4048ms: Process K terminated [Q J L B H F C A E D G I]
time 5227ms: Process A terminated [Q C F L E D H G I J B]
time 5633ms: Process L terminated [Q F C E D H G I J B]
time 18940ms: Process D terminated [Q G E H I J F B]
time 19359ms: Process E terminated [Q H I J F B]
time 23957ms: Process F terminated [Q B G I]
time 26382ms: Process C terminated [Q H J G B I]
time 28820ms: Process J terminated [Q G H B I]
time 29855ms: Process G terminated [Q I H B]
time 30136ms: Process H terminated [Q I B]
time 31258ms: Process B terminated [Q <empty>]
time 36162ms: Process I terminated [Q <empty>]
time 36164ms: Simulator ended for SJF [Q <empty>]

Process A [NEW] (arrival time 9 ms) 16 CPU bursts
Process B [NEW] (arrival time 18 ms) 21 CPU bursts
Process C [NEW] (arrival time 84 ms) 82 CPU bursts
Process D [NEW] (arrival time 86 ms) 36 CPU bursts
Process E [NEW] (arrival time 2 ms) 26 CPU bursts
Process F [NEW] (arrival time 25 ms) 39 CPU bursts
Process G [NEW] (arrival time 13 ms) 76 CPU bursts
Process H [NEW] (arrival time 46 ms) 82 CPU bursts
Process I [NEW] (arrival time 64 ms) 63 CPU bursts
Process J [NEW] (arrival time 31 ms) 21 CPU bursts
Process K [NEW] (arrival time 56 ms) 1 CPU burst
Process L [NEW] (arrival time 12 ms) 3 CPU bursts
time 0ms: Simulator started for SRT [Q <empty>]
time 2ms: Process E (tau 100ms) arrived; added to ready queue [Q E]
time 4ms: Process E started using the CPU for 11ms burst [Q <empty>]
time 9ms: Process A (tau 100ms) arrived; added to ready queue [Q A]
time 12ms: Process L (tau 100ms) arrived; added to ready queue [Q A L]
time 13ms: Process G (tau 100ms) arrived; added to ready queue [Q A G L]
time 15ms: Process E completed a CPU burst; 25 bursts to go [Q A G L]
time 15ms: Recalculated tau = 56ms for process E [Q A G L]
time 15ms: Process E switching out of CPU; will block on I/O until time 34ms [Q A G L]
time 18ms: Process B (tau 100ms) arrived; added to ready queue [Q B G L]
time 19ms: Process A started using the CPU for 56ms burst [Q B G L]
time 25ms: Process F (tau 100ms) arrived; added to ready queue [Q B F G L]
time 31ms: Process J (tau 100ms) arrived; added to ready queue [Q B F G J L]
time 34ms: Process E (tau 56ms) completed I/O and will preempt A [Q E B F G J L]
time 38ms: Process E started using the CPU for 65ms burst [Q A B F G J L]
time 46ms: Process H (tau 100ms) arrived; added to ready queue [Q A B F G H J L]
time 56ms: Process K (tau 100ms) arrived; added to ready queue [Q A B F G H J K L]
time 64ms: Process I (tau 100ms) arrived; added to ready queue [Q A B F G H I J K L]
time 84ms: Process C (tau 100ms) arrived; added to ready queue [Q A B C F G H I J K L]
time 86ms: Process D (tau 100ms) arrived; added to ready queue [Q A B C D F G H I J K L]
time 103ms: Process E completed a CPU burst; 24 bursts to go [Q A B C D F G H I J K L]
time 103ms: Recalculated tau = 61ms for process E [Q A B C D F G H I J K L]
time 103ms: Process E switching out of CPU; will block on I/O until time 160ms [Q A B C D F G H I J K L]
time 107ms: Process A started using the CPU with 41ms remaining [Q B C D F G H I J K L]
time 148ms: Process A completed a CPU burst; 15 bursts to go [Q B C D F G H I J K L]
time 148ms: Recalculated tau = 78ms for process A [Q B C D F G H I J K L]
time 148ms: Process A switching out of CPU; will block on I/O until time 173ms [Q B C D F G H I J K L]
time 152ms: Process B started using the CPU for 106ms burst [Q C D F G H I J K L]
time 160ms: Process E (tau 61ms) completed I/O and will preempt B [Q E C D F G H I J K L]
time 164ms: Process E started using the CPU for 52ms burst [Q B C D F G H I J K L]
time 173ms: Process A (tau 78ms) completed I/O; added to ready queue [Q A B C D F G H I J K L]
time 216ms: Process E completed a CPU burst; 23 bursts to go [Q A B C D F G H I J K L]
time 216ms: Recalculated tau = 57ms for process E [Q A B C D F G H I J K L]
time 216ms: Process E switching out of CPU; will block on I/O until time 314ms [Q A B C D F G H I J K L]
time 220ms: Process A started using the CPU for 60ms burst [Q B C D F G H I J K L]
time 280ms: Process A completed a CPU burst; 14 bursts to go [Q B C D F G H I J K L]
time 280ms: Recalculated tau = 69ms for process A [Q B C D F G H I J K L]
time 280ms: Process A switching out of CPU; will block on I/O until time 435ms [Q B C D F G H I J K L]
time 284ms: Process B started using the CPU with 98ms remaining [Q C D F G H I J K L]
time 314ms: Process E (tau 57ms) completed I/O and will preempt B [Q E C D F G H I J K L]
time 318ms: Process E started using the CPU for 199ms burst [Q B C D F G H I J K L]
time 435ms: Process A (tau 69ms) completed I/O; added to ready queue [Q B A C D F G H I J K L]
time 517ms: Process E completed a CPU burst; 22 bursts to go [Q B A C D F G H I J K L]
time 517ms: Recalculated tau = 128ms for process E [Q B A C D F G H I J K L]
time 517ms: Process E switching out of CPU; will block on I/O until time 529ms [Q B A C D F G H I J K L]
time 521ms: Process B started using the CPU with 68ms remaining [Q A C D F G H I J K L]
time 529ms: Process E (tau 128ms) completed I/O; added to ready queue [Q A C D F G H I J K L E]
time 589ms: Process B completed a CPU burst; 20 bursts to go [Q A C D F G H I J K L E]
time 589ms: Recalculated tau = 103ms for process B [Q A C D F G H I J K L E]
time 589ms: Process B switching out of CPU; will block on I/O until time 747ms [Q A C D F G H I J K L E]
time 593ms: Process A started using the CPU for 39ms burst [Q C D F G H I J K L E]
time 632ms: Process A completed a CPU burst; 13 bursts to go [Q C D F G H I J K L E]
time 632ms: Recalculated tau = 54ms for process A [Q C D F G H I J K L E]
time 632ms: Process A switching out of CPU; will block on I/O until time 684ms [Q C D F G H I J K L E]
time 636ms: Process C started using the CPU for 79ms burst [Q D F G H I J K L E]
time 684ms: Process A (tau 54ms) completed I/O; added to ready queue [Q A D F G H I J K L E]
time 715ms: Process C completed a CPU burst; 81 bursts to go [Q A D F G H I J K L E]
time 715ms: Recalculated tau = 90ms for process C [Q A D F G H I J K L E]
time 715ms: Process C switching out of CPU; will block on I/O until time 874ms [Q A D F G H I J K L E]
time 719ms: Process A started using the CPU for 47ms burst [Q D F G H I J K L E]
time 747ms: Process B (tau 103ms) completed I/O; added to ready queue [Q D F G H I J K L B E]
time 766ms: Process A completed a CPU burst; 12 bursts to go [Q D F G H I J K L B E]
time 766ms: Recalculated tau = 51ms for process A [Q D F G H I J K L B E]
time 766ms: Process A switching out of CPU; will block on I/O until time 770ms [Q D F G H I J K L B E]
time 770ms: Process D started using the CPU for 22ms burst [Q F G H I J K L B E]
time 770ms: Process A (tau 51ms) completed I/O and will preempt D [Q A F G H I J K L B E]
time 774ms: Process A started using the CPU for 137ms burst [Q D F G H I J K L B E]
time 874ms: Process C (tau 90ms) completed I/O; added to ready queue [Q C D F G H I J K L B E]
time 911ms: Process A completed a CPU burst; 11 bursts to go [Q C D F G H I J K L B E]
time 911ms: Recalculated tau = 94ms for process A [Q C D F G H I J K L B E]
time 911ms: Process A switching out of CPU; will block on I/O until time 937ms [Q C D F G H I J K L B E]
time 915ms: Process C started using the CPU for 148ms burst [Q D F G H I J K L B E]
time 937ms: Process A (tau 94ms) completed I/O; added to ready queue [Q A D F G H I J K L B E]
time 4241ms: Process K terminated [Q L B J H F C A E D G I]
time 5448ms: Process A terminated [Q C F L E D H G I J B]
time 5738ms: Process L terminated [Q C F E D H G I J B]
time 18853ms: Process E terminated [Q I J F B]
time 18958ms: Process D terminated [Q C G I J F B]
time 22753ms: Process C terminated [Q I H J F B]
time 24405ms: Process F terminated [Q B G]
time 28392ms: Process J terminated [Q G H B I]
time 29208ms: Process H terminated [Q G B I]
time 31375ms: Process G terminated [Q I B]
time 31553ms: Process B terminated [Q <empty>]
time 36882ms: Process I terminated [Q <empty>]
time 36884ms: Simulator ended for SRT [Q <empty>]
